2025-05-16 23:01:59,533 - INFO - 发送验证码: phone=16723456432, code=478179
2025-05-16 23:02:00,914 - INFO - SELECT DATABASE()
2025-05-16 23:02:00,914 - INFO - [raw sql] {}
2025-05-16 23:02:00,916 - INFO - SELECT @@sql_mode
2025-05-16 23:02:00,916 - INFO - [raw sql] {}
2025-05-16 23:02:00,917 - INFO - SELECT @@lower_case_table_names
2025-05-16 23:02:00,917 - INFO - [raw sql] {}
2025-05-16 23:02:00,919 - INFO - BEGIN (implicit)
2025-05-16 23:02:00,924 - INFO - SELECT users.phone, users.email, users.username, users.sex, users.description, users.photo, users.qrcode, users.password, users.id, users.created_at 
FROM users 
WHERE users.phone = %(phone_1)s
2025-05-16 23:02:00,925 - INFO - [generated in 0.00079s] {'phone_1': '16723456432'}
2025-05-16 23:02:00,927 - INFO - ROLLBACK
2025-05-16 23:02:02,449 - INFO - BEGIN (implicit)
2025-05-16 23:02:02,450 - INFO - SELECT users.phone, users.email, users.username, users.sex, users.description, users.photo, users.qrcode, users.password, users.id, users.created_at 
FROM users 
WHERE users.id = %(id_1)s
2025-05-16 23:02:02,450 - INFO - [generated in 0.00034s] {'id_1': 22}
2025-05-16 23:02:02,453 - INFO - SELECT users.phone, users.email, users.username, users.sex, users.description, users.photo, users.qrcode, users.password, users.id, users.created_at 
FROM users 
WHERE users.id = %(id_1)s
2025-05-16 23:02:02,453 - INFO - [cached since 0.003255s ago] {'id_1': 22}
2025-05-16 23:02:02,456 - INFO - SELECT users.phone, users.email, users.username, users.sex, users.description, users.photo, users.qrcode, users.password, users.id, users.created_at 
FROM users 
WHERE users.id = %(id_1)s
2025-05-16 23:02:02,457 - INFO - [cached since 0.006639s ago] {'id_1': 22}
2025-05-16 23:02:02,458 - INFO - SELECT users.phone, users.email, users.username, users.sex, users.description, users.photo, users.qrcode, users.password, users.id, users.created_at 
FROM users 
WHERE users.id = %(id_1)s
2025-05-16 23:02:02,459 - INFO - [cached since 0.0086s ago] {'id_1': 22}
2025-05-16 23:02:02,460 - INFO - SELECT users.phone, users.email, users.username, users.sex, users.description, users.photo, users.qrcode, users.password, users.id, users.created_at 
FROM users 
WHERE users.id = %(id_1)s
2025-05-16 23:02:02,460 - INFO - [cached since 0.01041s ago] {'id_1': 22}
2025-05-16 23:02:02,462 - INFO - SELECT users.phone, users.email, users.username, users.sex, users.description, users.photo, users.qrcode, users.password, users.id, users.created_at 
FROM users 
WHERE users.id = %(id_1)s
2025-05-16 23:02:02,463 - INFO - [cached since 0.01327s ago] {'id_1': 22}
2025-05-16 23:02:02,465 - INFO - SELECT users.phone, users.email, users.username, users.sex, users.description, users.photo, users.qrcode, users.password, users.id, users.created_at 
FROM users 
WHERE users.id = %(id_1)s
2025-05-16 23:02:02,465 - INFO - [cached since 0.01533s ago] {'id_1': 22}
2025-05-16 23:02:02,467 - INFO - SELECT users.phone, users.email, users.username, users.sex, users.description, users.photo, users.qrcode, users.password, users.id, users.created_at 
FROM users 
WHERE users.id = %(id_1)s
2025-05-16 23:02:02,467 - INFO - [cached since 0.01751s ago] {'id_1': 22}
2025-05-16 23:02:02,469 - INFO - SELECT users.phone, users.email, users.username, users.sex, users.description, users.photo, users.qrcode, users.password, users.id, users.created_at 
FROM users 
WHERE users.id = %(id_1)s
2025-05-16 23:02:02,470 - INFO - [cached since 0.01987s ago] {'id_1': 22}
2025-05-16 23:02:02,472 - INFO - SELECT users.phone, users.email, users.username, users.sex, users.description, users.photo, users.qrcode, users.password, users.id, users.created_at 
FROM users 
WHERE users.id = %(id_1)s
2025-05-16 23:02:02,472 - INFO - [cached since 0.02226s ago] {'id_1': 22}
2025-05-16 23:02:02,475 - INFO - ROLLBACK
2025-05-16 23:02:11,759 - INFO - BEGIN (implicit)
2025-05-16 23:02:11,760 - INFO - SELECT users.phone, users.email, users.username, users.sex, users.description, users.photo, users.qrcode, users.password, users.id, users.created_at 
FROM users 
WHERE users.id = %(id_1)s
2025-05-16 23:02:11,760 - INFO - [cached since 9.31s ago] {'id_1': 22}
2025-05-16 23:02:11,764 - INFO - SELECT users.phone, users.email, users.username, users.sex, users.description, users.photo, users.qrcode, users.password, users.id, users.created_at 
FROM users 
WHERE users.id = %(id_1)s
2025-05-16 23:02:11,764 - INFO - [cached since 9.314s ago] {'id_1': 22}
2025-05-16 23:02:11,766 - INFO - SELECT users.phone, users.email, users.username, users.sex, users.description, users.photo, users.qrcode, users.password, users.id, users.created_at 
FROM users 
WHERE users.id = %(id_1)s
2025-05-16 23:02:11,767 - INFO - [cached since 9.317s ago] {'id_1': 32}
2025-05-16 23:02:11,768 - INFO - SELECT users.phone, users.email, users.username, users.sex, users.description, users.photo, users.qrcode, users.password, users.id, users.created_at 
FROM users 
WHERE users.id = %(id_1)s
2025-05-16 23:02:11,768 - INFO - [cached since 9.318s ago] {'id_1': 32}
2025-05-16 23:02:11,771 - INFO - SELECT users.phone, users.email, users.username, users.sex, users.description, users.photo, users.qrcode, users.password, users.id, users.created_at 
FROM users 
WHERE users.id = %(id_1)s
2025-05-16 23:02:11,772 - INFO - [cached since 9.322s ago] {'id_1': 32}
2025-05-16 23:02:11,774 - INFO - SELECT users.phone, users.email, users.username, users.sex, users.description, users.photo, users.qrcode, users.password, users.id, users.created_at 
FROM users 
WHERE users.id = %(id_1)s
2025-05-16 23:02:11,774 - INFO - [cached since 9.324s ago] {'id_1': 11}
2025-05-16 23:02:11,775 - INFO - SELECT users.phone, users.email, users.username, users.sex, users.description, users.photo, users.qrcode, users.password, users.id, users.created_at 
FROM users 
WHERE users.id = %(id_1)s
2025-05-16 23:02:11,776 - INFO - [cached since 9.326s ago] {'id_1': 6}
2025-05-16 23:02:11,778 - INFO - SELECT users.phone, users.email, users.username, users.sex, users.description, users.photo, users.qrcode, users.password, users.id, users.created_at 
FROM users 
WHERE users.id = %(id_1)s
2025-05-16 23:02:11,778 - INFO - [cached since 9.328s ago] {'id_1': 6}
2025-05-16 23:02:11,780 - INFO - SELECT users.phone, users.email, users.username, users.sex, users.description, users.photo, users.qrcode, users.password, users.id, users.created_at 
FROM users 
WHERE users.id = %(id_1)s
2025-05-16 23:02:11,780 - INFO - [cached since 9.33s ago] {'id_1': 6}
2025-05-16 23:02:11,781 - INFO - SELECT users.phone, users.email, users.username, users.sex, users.description, users.photo, users.qrcode, users.password, users.id, users.created_at 
FROM users 
WHERE users.id = %(id_1)s
2025-05-16 23:02:11,782 - INFO - [cached since 9.332s ago] {'id_1': 6}
2025-05-16 23:02:11,784 - INFO - ROLLBACK
2025-05-16 23:03:27,250 - INFO - BEGIN (implicit)
2025-05-16 23:03:27,250 - INFO - SELECT users.phone, users.email, users.username, users.sex, users.description, users.photo, users.qrcode, users.password, users.id, users.created_at 
FROM users 
WHERE users.id = %(id_1)s
2025-05-16 23:03:27,251 - INFO - [cached since 84.8s ago] {'id_1': 22}
2025-05-16 23:03:27,253 - INFO - ROLLBACK
2025-05-16 23:18:47,783 - INFO - Error while receiving.
Traceback (most recent call last):
  File "D:\conda\lib\site-packages\py4j\clientserver.py", line 511, in send_command
    answer = smart_decode(self.stream.readline()[:-1])
  File "D:\conda\lib\socket.py", line 669, in readinto
    return self._sock.recv_into(b)
ConnectionResetError: [WinError 10054] 远程主机强迫关闭了一个现有的连接。
2025-05-16 23:18:47,905 - INFO - Closing down clientserver connection
2025-05-16 23:18:47,906 - ERROR - Exception while sending command.
Traceback (most recent call last):
  File "D:\conda\lib\site-packages\py4j\clientserver.py", line 511, in send_command
    answer = smart_decode(self.stream.readline()[:-1])
  File "D:\conda\lib\socket.py", line 669, in readinto
    return self._sock.recv_into(b)
ConnectionResetError: [WinError 10054] 远程主机强迫关闭了一个现有的连接。

During handling of the above exception, another exception occurred:

Traceback (most recent call last):
  File "D:\conda\lib\site-packages\py4j\java_gateway.py", line 1038, in send_command
    response = connection.send_command(command)
  File "D:\conda\lib\site-packages\py4j\clientserver.py", line 539, in send_command
    raise Py4JNetworkError(
py4j.protocol.Py4JNetworkError: Error while sending or receiving
2025-05-16 23:18:47,907 - INFO - Closing down clientserver connection
2025-05-16 23:22:39,366 - INFO - SELECT DATABASE()
2025-05-16 23:22:39,367 - INFO - [raw sql] {}
2025-05-16 23:22:39,368 - INFO - SELECT @@sql_mode
2025-05-16 23:22:39,368 - INFO - [raw sql] {}
2025-05-16 23:22:39,368 - INFO - SELECT @@lower_case_table_names
2025-05-16 23:22:39,369 - INFO - [raw sql] {}
2025-05-16 23:22:39,369 - INFO - BEGIN (implicit)
2025-05-16 23:22:39,375 - INFO - SELECT users.phone, users.email, users.username, users.sex, users.description, users.photo, users.qrcode, users.password, users.id, users.created_at 
FROM users 
WHERE users.id = %(id_1)s
2025-05-16 23:22:39,375 - INFO - [generated in 0.00029s] {'id_1': 22}
2025-05-16 23:22:39,379 - INFO - ROLLBACK
2025-05-16 23:37:28,717 - INFO - Error while receiving.
Traceback (most recent call last):
  File "D:\conda\lib\site-packages\py4j\clientserver.py", line 511, in send_command
    answer = smart_decode(self.stream.readline()[:-1])
  File "D:\conda\lib\socket.py", line 669, in readinto
    return self._sock.recv_into(b)
ConnectionResetError: [WinError 10054] 远程主机强迫关闭了一个现有的连接。
2025-05-16 23:37:28,719 - INFO - Closing down clientserver connection
2025-05-16 23:37:28,719 - ERROR - Exception while sending command.
Traceback (most recent call last):
  File "D:\conda\lib\site-packages\py4j\clientserver.py", line 511, in send_command
    answer = smart_decode(self.stream.readline()[:-1])
  File "D:\conda\lib\socket.py", line 669, in readinto
    return self._sock.recv_into(b)
ConnectionResetError: [WinError 10054] 远程主机强迫关闭了一个现有的连接。

During handling of the above exception, another exception occurred:

Traceback (most recent call last):
  File "D:\conda\lib\site-packages\py4j\java_gateway.py", line 1038, in send_command
    response = connection.send_command(command)
  File "D:\conda\lib\site-packages\py4j\clientserver.py", line 539, in send_command
    raise Py4JNetworkError(
py4j.protocol.Py4JNetworkError: Error while sending or receiving
2025-05-16 23:37:28,721 - INFO - Closing down clientserver connection
2025-05-16 23:37:47,903 - INFO - SELECT DATABASE()
2025-05-16 23:37:47,904 - INFO - [raw sql] {}
2025-05-16 23:37:47,905 - INFO - SELECT @@sql_mode
2025-05-16 23:37:47,905 - INFO - [raw sql] {}
2025-05-16 23:37:47,906 - INFO - SELECT @@lower_case_table_names
2025-05-16 23:37:47,907 - INFO - [raw sql] {}
2025-05-16 23:37:47,909 - INFO - BEGIN (implicit)
2025-05-16 23:37:47,916 - INFO - SELECT users.phone, users.email, users.username, users.sex, users.description, users.photo, users.qrcode, users.password, users.id, users.created_at 
FROM users 
WHERE users.id = %(id_1)s
2025-05-16 23:37:47,916 - INFO - [generated in 0.00045s] {'id_1': 22}
2025-05-16 23:37:47,919 - INFO - ROLLBACK
2025-05-16 23:41:16,240 - INFO - Error while receiving.
Traceback (most recent call last):
  File "D:\conda\lib\site-packages\py4j\clientserver.py", line 511, in send_command
    answer = smart_decode(self.stream.readline()[:-1])
  File "D:\conda\lib\socket.py", line 669, in readinto
    return self._sock.recv_into(b)
ConnectionResetError: [WinError 10054] 远程主机强迫关闭了一个现有的连接。
2025-05-16 23:41:16,243 - INFO - Closing down clientserver connection
2025-05-16 23:41:16,243 - ERROR - Exception while sending command.
Traceback (most recent call last):
  File "D:\conda\lib\site-packages\py4j\clientserver.py", line 511, in send_command
    answer = smart_decode(self.stream.readline()[:-1])
  File "D:\conda\lib\socket.py", line 669, in readinto
    return self._sock.recv_into(b)
ConnectionResetError: [WinError 10054] 远程主机强迫关闭了一个现有的连接。

During handling of the above exception, another exception occurred:

Traceback (most recent call last):
  File "D:\conda\lib\site-packages\py4j\java_gateway.py", line 1038, in send_command
    response = connection.send_command(command)
  File "D:\conda\lib\site-packages\py4j\clientserver.py", line 539, in send_command
    raise Py4JNetworkError(
py4j.protocol.Py4JNetworkError: Error while sending or receiving
2025-05-16 23:41:16,244 - INFO - Closing down clientserver connection
2025-05-16 23:41:41,261 - INFO - SELECT DATABASE()
2025-05-16 23:41:41,262 - INFO - [raw sql] {}
2025-05-16 23:41:41,263 - INFO - SELECT @@sql_mode
2025-05-16 23:41:41,265 - INFO - [raw sql] {}
2025-05-16 23:41:41,265 - INFO - SELECT @@lower_case_table_names
2025-05-16 23:41:41,266 - INFO - [raw sql] {}
2025-05-16 23:41:41,267 - INFO - BEGIN (implicit)
2025-05-16 23:41:41,277 - INFO - SELECT users.phone, users.email, users.username, users.sex, users.description, users.photo, users.qrcode, users.password, users.id, users.created_at 
FROM users 
WHERE users.id = %(id_1)s
2025-05-16 23:41:41,277 - INFO - [generated in 0.00054s] {'id_1': 22}
2025-05-16 23:41:41,280 - INFO - SELECT users.phone, users.email, users.username, users.sex, users.description, users.photo, users.qrcode, users.password, users.id, users.created_at 
FROM users 
WHERE users.id = %(id_1)s
2025-05-16 23:41:41,281 - INFO - [cached since 0.004186s ago] {'id_1': 22}
2025-05-16 23:41:41,283 - INFO - SELECT users.phone, users.email, users.username, users.sex, users.description, users.photo, users.qrcode, users.password, users.id, users.created_at 
FROM users 
WHERE users.id = %(id_1)s
2025-05-16 23:41:41,283 - INFO - [cached since 0.006825s ago] {'id_1': 22}
2025-05-16 23:41:41,286 - INFO - SELECT users.phone, users.email, users.username, users.sex, users.description, users.photo, users.qrcode, users.password, users.id, users.created_at 
FROM users 
WHERE users.id = %(id_1)s
2025-05-16 23:41:41,286 - INFO - [cached since 0.009474s ago] {'id_1': 22}
2025-05-16 23:41:41,288 - INFO - SELECT users.phone, users.email, users.username, users.sex, users.description, users.photo, users.qrcode, users.password, users.id, users.created_at 
FROM users 
WHERE users.id = %(id_1)s
2025-05-16 23:41:41,290 - INFO - [cached since 0.01276s ago] {'id_1': 22}
2025-05-16 23:41:41,293 - INFO - ROLLBACK
2025-05-16 23:50:14,812 - INFO - Error while receiving.
Traceback (most recent call last):
  File "D:\conda\lib\site-packages\py4j\clientserver.py", line 511, in send_command
    answer = smart_decode(self.stream.readline()[:-1])
  File "D:\conda\lib\socket.py", line 669, in readinto
    return self._sock.recv_into(b)
ConnectionResetError: [WinError 10054] 远程主机强迫关闭了一个现有的连接。
2025-05-16 23:50:14,815 - INFO - Closing down clientserver connection
2025-05-16 23:50:14,816 - ERROR - Exception while sending command.
Traceback (most recent call last):
  File "D:\conda\lib\site-packages\py4j\clientserver.py", line 511, in send_command
    answer = smart_decode(self.stream.readline()[:-1])
  File "D:\conda\lib\socket.py", line 669, in readinto
    return self._sock.recv_into(b)
ConnectionResetError: [WinError 10054] 远程主机强迫关闭了一个现有的连接。

During handling of the above exception, another exception occurred:

Traceback (most recent call last):
  File "D:\conda\lib\site-packages\py4j\java_gateway.py", line 1038, in send_command
    response = connection.send_command(command)
  File "D:\conda\lib\site-packages\py4j\clientserver.py", line 539, in send_command
    raise Py4JNetworkError(
py4j.protocol.Py4JNetworkError: Error while sending or receiving
2025-05-16 23:50:14,818 - INFO - Closing down clientserver connection
2025-05-16 23:51:12,572 - INFO - Error while sending or receiving.
Traceback (most recent call last):
  File "D:\conda\lib\site-packages\pyspark\errors\exceptions\captured.py", line 169, in deco
    return f(*a, **kw)
  File "D:\conda\lib\site-packages\py4j\protocol.py", line 326, in get_return_value
    raise Py4JJavaError(
py4j.protocol.Py4JJavaError: <exception str() failed>

During handling of the above exception, another exception occurred:

Traceback (most recent call last):
  File "D:\conda\lib\site-packages\py4j\clientserver.py", line 511, in send_command
    answer = smart_decode(self.stream.readline()[:-1])
  File "D:\conda\lib\socket.py", line 669, in readinto
    return self._sock.recv_into(b)
ConnectionResetError: [WinError 10054] 远程主机强迫关闭了一个现有的连接。

During handling of the above exception, another exception occurred:

Traceback (most recent call last):
  File "D:\conda\lib\site-packages\py4j\clientserver.py", line 503, in send_command
    self.socket.sendall(command.encode("utf-8"))
ConnectionResetError: [WinError 10054] 远程主机强迫关闭了一个现有的连接。

During handling of the above exception, another exception occurred:

Traceback (most recent call last):
  File "D:\conda\lib\site-packages\py4j\clientserver.py", line 503, in send_command
    self.socket.sendall(command.encode("utf-8"))
ConnectionResetError: [WinError 10054] 远程主机强迫关闭了一个现有的连接。

During handling of the above exception, another exception occurred:

Traceback (most recent call last):
  File "D:\conda\lib\site-packages\py4j\clientserver.py", line 503, in send_command
    self.socket.sendall(command.encode("utf-8"))
ConnectionResetError: [WinError 10054] 远程主机强迫关闭了一个现有的连接。

During handling of the above exception, another exception occurred:

Traceback (most recent call last):
  File "D:\conda\lib\site-packages\py4j\clientserver.py", line 503, in send_command
    self.socket.sendall(command.encode("utf-8"))
ConnectionResetError: [WinError 10054] 远程主机强迫关闭了一个现有的连接。

During handling of the above exception, another exception occurred:

Traceback (most recent call last):
  File "D:\conda\lib\site-packages\py4j\clientserver.py", line 503, in send_command
    self.socket.sendall(command.encode("utf-8"))
ConnectionResetError: [WinError 10054] 远程主机强迫关闭了一个现有的连接。

During handling of the above exception, another exception occurred:

Traceback (most recent call last):
  File "D:\conda\lib\site-packages\py4j\clientserver.py", line 503, in send_command
    self.socket.sendall(command.encode("utf-8"))
ConnectionResetError: [WinError 10054] 远程主机强迫关闭了一个现有的连接。

During handling of the above exception, another exception occurred:

Traceback (most recent call last):
  File "D:\conda\lib\site-packages\py4j\clientserver.py", line 503, in send_command
    self.socket.sendall(command.encode("utf-8"))
ConnectionResetError: [WinError 10054] 远程主机强迫关闭了一个现有的连接。

During handling of the above exception, another exception occurred:

Traceback (most recent call last):
  File "D:\conda\lib\site-packages\py4j\clientserver.py", line 503, in send_command
    self.socket.sendall(command.encode("utf-8"))
ConnectionResetError: [WinError 10054] 远程主机强迫关闭了一个现有的连接。

During handling of the above exception, another exception occurred:

Traceback (most recent call last):
  File "D:\conda\lib\site-packages\py4j\clientserver.py", line 503, in send_command
    self.socket.sendall(command.encode("utf-8"))
ConnectionResetError: [WinError 10054] 远程主机强迫关闭了一个现有的连接。

During handling of the above exception, another exception occurred:

Traceback (most recent call last):
  File "D:\conda\lib\site-packages\py4j\clientserver.py", line 503, in send_command
    self.socket.sendall(command.encode("utf-8"))
ConnectionResetError: [WinError 10054] 远程主机强迫关闭了一个现有的连接。

During handling of the above exception, another exception occurred:

Traceback (most recent call last):
  File "D:\conda\lib\site-packages\py4j\clientserver.py", line 503, in send_command
    self.socket.sendall(command.encode("utf-8"))
ConnectionResetError: [WinError 10054] 远程主机强迫关闭了一个现有的连接。

During handling of the above exception, another exception occurred:

Traceback (most recent call last):
  File "D:\conda\lib\site-packages\py4j\clientserver.py", line 503, in send_command
    self.socket.sendall(command.encode("utf-8"))
ConnectionResetError: [WinError 10054] 远程主机强迫关闭了一个现有的连接。

During handling of the above exception, another exception occurred:

Traceback (most recent call last):
  File "D:\conda\lib\site-packages\py4j\clientserver.py", line 503, in send_command
    self.socket.sendall(command.encode("utf-8"))
ConnectionResetError: [WinError 10054] 远程主机强迫关闭了一个现有的连接。

During handling of the above exception, another exception occurred:

Traceback (most recent call last):
  File "D:\conda\lib\site-packages\py4j\clientserver.py", line 503, in send_command
    self.socket.sendall(command.encode("utf-8"))
ConnectionResetError: [WinError 10054] 远程主机强迫关闭了一个现有的连接。

During handling of the above exception, another exception occurred:

Traceback (most recent call last):
  File "D:\conda\lib\site-packages\py4j\clientserver.py", line 503, in send_command
    self.socket.sendall(command.encode("utf-8"))
ConnectionResetError: [WinError 10054] 远程主机强迫关闭了一个现有的连接。

During handling of the above exception, another exception occurred:

Traceback (most recent call last):
  File "D:\conda\lib\site-packages\py4j\clientserver.py", line 503, in send_command
    self.socket.sendall(command.encode("utf-8"))
ConnectionResetError: [WinError 10054] 远程主机强迫关闭了一个现有的连接。

During handling of the above exception, another exception occurred:

Traceback (most recent call last):
  File "D:\conda\lib\site-packages\py4j\clientserver.py", line 503, in send_command
    self.socket.sendall(command.encode("utf-8"))
ConnectionResetError: [WinError 10054] 远程主机强迫关闭了一个现有的连接。

During handling of the above exception, another exception occurred:

Traceback (most recent call last):
  File "D:\conda\lib\site-packages\py4j\clientserver.py", line 503, in send_command
    self.socket.sendall(command.encode("utf-8"))
ConnectionResetError: [WinError 10054] 远程主机强迫关闭了一个现有的连接。

During handling of the above exception, another exception occurred:

Traceback (most recent call last):
  File "D:\conda\lib\site-packages\py4j\clientserver.py", line 503, in send_command
    self.socket.sendall(command.encode("utf-8"))
ConnectionResetError: [WinError 10054] 远程主机强迫关闭了一个现有的连接。

During handling of the above exception, another exception occurred:

Traceback (most recent call last):
  File "D:\conda\lib\site-packages\py4j\clientserver.py", line 503, in send_command
    self.socket.sendall(command.encode("utf-8"))
ConnectionResetError: [WinError 10054] 远程主机强迫关闭了一个现有的连接。

During handling of the above exception, another exception occurred:

Traceback (most recent call last):
  File "D:\conda\lib\site-packages\py4j\clientserver.py", line 503, in send_command
    self.socket.sendall(command.encode("utf-8"))
ConnectionResetError: [WinError 10054] 远程主机强迫关闭了一个现有的连接。

During handling of the above exception, another exception occurred:

Traceback (most recent call last):
  File "D:\conda\lib\site-packages\py4j\clientserver.py", line 503, in send_command
    self.socket.sendall(command.encode("utf-8"))
ConnectionResetError: [WinError 10054] 远程主机强迫关闭了一个现有的连接。

During handling of the above exception, another exception occurred:

Traceback (most recent call last):
  File "D:\conda\lib\site-packages\py4j\clientserver.py", line 503, in send_command
    self.socket.sendall(command.encode("utf-8"))
ConnectionResetError: [WinError 10054] 远程主机强迫关闭了一个现有的连接。

During handling of the above exception, another exception occurred:

Traceback (most recent call last):
  File "D:\conda\lib\site-packages\py4j\clientserver.py", line 503, in send_command
    self.socket.sendall(command.encode("utf-8"))
ConnectionResetError: [WinError 10054] 远程主机强迫关闭了一个现有的连接。

During handling of the above exception, another exception occurred:

Traceback (most recent call last):
  File "D:\conda\lib\site-packages\py4j\clientserver.py", line 503, in send_command
    self.socket.sendall(command.encode("utf-8"))
ConnectionResetError: [WinError 10054] 远程主机强迫关闭了一个现有的连接。

During handling of the above exception, another exception occurred:

Traceback (most recent call last):
  File "D:\conda\lib\site-packages\py4j\clientserver.py", line 503, in send_command
    self.socket.sendall(command.encode("utf-8"))
ConnectionResetError: [WinError 10054] 远程主机强迫关闭了一个现有的连接。

During handling of the above exception, another exception occurred:

Traceback (most recent call last):
  File "D:\conda\lib\site-packages\py4j\clientserver.py", line 503, in send_command
    self.socket.sendall(command.encode("utf-8"))
ConnectionResetError: [WinError 10054] 远程主机强迫关闭了一个现有的连接。

During handling of the above exception, another exception occurred:

Traceback (most recent call last):
  File "D:\conda\lib\site-packages\py4j\clientserver.py", line 503, in send_command
    self.socket.sendall(command.encode("utf-8"))
ConnectionResetError: [WinError 10054] 远程主机强迫关闭了一个现有的连接。

During handling of the above exception, another exception occurred:

Traceback (most recent call last):
  File "D:\conda\lib\site-packages\py4j\clientserver.py", line 503, in send_command
    self.socket.sendall(command.encode("utf-8"))
ConnectionResetError: [WinError 10054] 远程主机强迫关闭了一个现有的连接。

During handling of the above exception, another exception occurred:

Traceback (most recent call last):
  File "D:\conda\lib\site-packages\py4j\clientserver.py", line 503, in send_command
    self.socket.sendall(command.encode("utf-8"))
ConnectionResetError: [WinError 10054] 远程主机强迫关闭了一个现有的连接。

During handling of the above exception, another exception occurred:

Traceback (most recent call last):
  File "D:\conda\lib\site-packages\py4j\clientserver.py", line 503, in send_command
    self.socket.sendall(command.encode("utf-8"))
ConnectionResetError: [WinError 10054] 远程主机强迫关闭了一个现有的连接。

During handling of the above exception, another exception occurred:

Traceback (most recent call last):
  File "D:\conda\lib\site-packages\py4j\clientserver.py", line 503, in send_command
    self.socket.sendall(command.encode("utf-8"))
ConnectionResetError: [WinError 10054] 远程主机强迫关闭了一个现有的连接。

During handling of the above exception, another exception occurred:

Traceback (most recent call last):
  File "D:\conda\lib\site-packages\py4j\clientserver.py", line 503, in send_command
    self.socket.sendall(command.encode("utf-8"))
ConnectionResetError: [WinError 10054] 远程主机强迫关闭了一个现有的连接。

During handling of the above exception, another exception occurred:

Traceback (most recent call last):
  File "D:\conda\lib\site-packages\py4j\clientserver.py", line 503, in send_command
    self.socket.sendall(command.encode("utf-8"))
ConnectionResetError: [WinError 10054] 远程主机强迫关闭了一个现有的连接。

During handling of the above exception, another exception occurred:

Traceback (most recent call last):
  File "D:\conda\lib\site-packages\py4j\clientserver.py", line 503, in send_command
    self.socket.sendall(command.encode("utf-8"))
ConnectionResetError: [WinError 10054] 远程主机强迫关闭了一个现有的连接。

During handling of the above exception, another exception occurred:

Traceback (most recent call last):
  File "D:\conda\lib\site-packages\py4j\clientserver.py", line 503, in send_command
    self.socket.sendall(command.encode("utf-8"))
ConnectionResetError: [WinError 10054] 远程主机强迫关闭了一个现有的连接。

During handling of the above exception, another exception occurred:

Traceback (most recent call last):
  File "D:\conda\lib\site-packages\py4j\clientserver.py", line 503, in send_command
    self.socket.sendall(command.encode("utf-8"))
ConnectionResetError: [WinError 10054] 远程主机强迫关闭了一个现有的连接。

During handling of the above exception, another exception occurred:

Traceback (most recent call last):
  File "D:\conda\lib\site-packages\py4j\clientserver.py", line 503, in send_command
    self.socket.sendall(command.encode("utf-8"))
ConnectionResetError: [WinError 10054] 远程主机强迫关闭了一个现有的连接。

During handling of the above exception, another exception occurred:

Traceback (most recent call last):
  File "D:\conda\lib\site-packages\py4j\clientserver.py", line 503, in send_command
    self.socket.sendall(command.encode("utf-8"))
ConnectionResetError: [WinError 10054] 远程主机强迫关闭了一个现有的连接。

During handling of the above exception, another exception occurred:

Traceback (most recent call last):
  File "D:\conda\lib\site-packages\py4j\clientserver.py", line 503, in send_command
    self.socket.sendall(command.encode("utf-8"))
ConnectionResetError: [WinError 10054] 远程主机强迫关闭了一个现有的连接。

During handling of the above exception, another exception occurred:

Traceback (most recent call last):
  File "D:\conda\lib\site-packages\py4j\clientserver.py", line 503, in send_command
    self.socket.sendall(command.encode("utf-8"))
ConnectionResetError: [WinError 10054] 远程主机强迫关闭了一个现有的连接。

During handling of the above exception, another exception occurred:

Traceback (most recent call last):
  File "D:\conda\lib\site-packages\py4j\clientserver.py", line 503, in send_command
    self.socket.sendall(command.encode("utf-8"))
ConnectionResetError: [WinError 10054] 远程主机强迫关闭了一个现有的连接。

During handling of the above exception, another exception occurred:

Traceback (most recent call last):
  File "D:\conda\lib\site-packages\py4j\clientserver.py", line 503, in send_command
    self.socket.sendall(command.encode("utf-8"))
ConnectionResetError: [WinError 10054] 远程主机强迫关闭了一个现有的连接。

During handling of the above exception, another exception occurred:

Traceback (most recent call last):
  File "D:\conda\lib\site-packages\py4j\clientserver.py", line 503, in send_command
    self.socket.sendall(command.encode("utf-8"))
ConnectionResetError: [WinError 10054] 远程主机强迫关闭了一个现有的连接。

During handling of the above exception, another exception occurred:

Traceback (most recent call last):
  File "D:\conda\lib\site-packages\py4j\clientserver.py", line 503, in send_command
    self.socket.sendall(command.encode("utf-8"))
ConnectionResetError: [WinError 10054] 远程主机强迫关闭了一个现有的连接。
2025-05-16 23:51:12,580 - INFO - Closing down clientserver connection
2025-05-16 23:51:14,605 - INFO - Closing down clientserver connection
2025-05-16 23:51:14,605 - INFO - Closing down clientserver connection
2025-05-16 23:51:12,580 - INFO - Exception while sending command.
Traceback (most recent call last):
  File "D:\conda\lib\site-packages\pyspark\errors\exceptions\captured.py", line 169, in deco
    return f(*a, **kw)
  File "D:\conda\lib\site-packages\py4j\protocol.py", line 326, in get_return_value
    raise Py4JJavaError(
py4j.protocol.Py4JJavaError: <exception str() failed>

During handling of the above exception, another exception occurred:

Traceback (most recent call last):
  File "D:\conda\lib\site-packages\py4j\clientserver.py", line 511, in send_command
    answer = smart_decode(self.stream.readline()[:-1])
  File "D:\conda\lib\socket.py", line 669, in readinto
    return self._sock.recv_into(b)
ConnectionResetError: [WinError 10054] 远程主机强迫关闭了一个现有的连接。

During handling of the above exception, another exception occurred:

Traceback (most recent call last):
  File "D:\conda\lib\site-packages\py4j\clientserver.py", line 503, in send_command
    self.socket.sendall(command.encode("utf-8"))
ConnectionResetError: [WinError 10054] 远程主机强迫关闭了一个现有的连接。

During handling of the above exception, another exception occurred:

Traceback (most recent call last):
  File "D:\conda\lib\site-packages\py4j\clientserver.py", line 503, in send_command
    self.socket.sendall(command.encode("utf-8"))
ConnectionResetError: [WinError 10054] 远程主机强迫关闭了一个现有的连接。

During handling of the above exception, another exception occurred:

Traceback (most recent call last):
  File "D:\conda\lib\site-packages\py4j\clientserver.py", line 503, in send_command
    self.socket.sendall(command.encode("utf-8"))
ConnectionResetError: [WinError 10054] 远程主机强迫关闭了一个现有的连接。

During handling of the above exception, another exception occurred:

Traceback (most recent call last):
  File "D:\conda\lib\site-packages\py4j\clientserver.py", line 503, in send_command
    self.socket.sendall(command.encode("utf-8"))
ConnectionResetError: [WinError 10054] 远程主机强迫关闭了一个现有的连接。

During handling of the above exception, another exception occurred:

Traceback (most recent call last):
  File "D:\conda\lib\site-packages\py4j\clientserver.py", line 503, in send_command
    self.socket.sendall(command.encode("utf-8"))
ConnectionResetError: [WinError 10054] 远程主机强迫关闭了一个现有的连接。

During handling of the above exception, another exception occurred:

Traceback (most recent call last):
  File "D:\conda\lib\site-packages\py4j\clientserver.py", line 503, in send_command
    self.socket.sendall(command.encode("utf-8"))
ConnectionResetError: [WinError 10054] 远程主机强迫关闭了一个现有的连接。

During handling of the above exception, another exception occurred:

Traceback (most recent call last):
  File "D:\conda\lib\site-packages\py4j\clientserver.py", line 503, in send_command
    self.socket.sendall(command.encode("utf-8"))
ConnectionResetError: [WinError 10054] 远程主机强迫关闭了一个现有的连接。

During handling of the above exception, another exception occurred:

Traceback (most recent call last):
  File "D:\conda\lib\site-packages\py4j\clientserver.py", line 503, in send_command
    self.socket.sendall(command.encode("utf-8"))
ConnectionResetError: [WinError 10054] 远程主机强迫关闭了一个现有的连接。

During handling of the above exception, another exception occurred:

Traceback (most recent call last):
  File "D:\conda\lib\site-packages\py4j\clientserver.py", line 503, in send_command
    self.socket.sendall(command.encode("utf-8"))
ConnectionResetError: [WinError 10054] 远程主机强迫关闭了一个现有的连接。

During handling of the above exception, another exception occurred:

Traceback (most recent call last):
  File "D:\conda\lib\site-packages\py4j\clientserver.py", line 503, in send_command
    self.socket.sendall(command.encode("utf-8"))
ConnectionResetError: [WinError 10054] 远程主机强迫关闭了一个现有的连接。

During handling of the above exception, another exception occurred:

Traceback (most recent call last):
  File "D:\conda\lib\site-packages\py4j\clientserver.py", line 503, in send_command
    self.socket.sendall(command.encode("utf-8"))
ConnectionResetError: [WinError 10054] 远程主机强迫关闭了一个现有的连接。

During handling of the above exception, another exception occurred:

Traceback (most recent call last):
  File "D:\conda\lib\site-packages\py4j\clientserver.py", line 503, in send_command
    self.socket.sendall(command.encode("utf-8"))
ConnectionResetError: [WinError 10054] 远程主机强迫关闭了一个现有的连接。

During handling of the above exception, another exception occurred:

Traceback (most recent call last):
  File "D:\conda\lib\site-packages\py4j\clientserver.py", line 503, in send_command
    self.socket.sendall(command.encode("utf-8"))
ConnectionResetError: [WinError 10054] 远程主机强迫关闭了一个现有的连接。

During handling of the above exception, another exception occurred:

Traceback (most recent call last):
  File "D:\conda\lib\site-packages\py4j\clientserver.py", line 503, in send_command
    self.socket.sendall(command.encode("utf-8"))
ConnectionResetError: [WinError 10054] 远程主机强迫关闭了一个现有的连接。

During handling of the above exception, another exception occurred:

Traceback (most recent call last):
  File "D:\conda\lib\site-packages\py4j\clientserver.py", line 503, in send_command
    self.socket.sendall(command.encode("utf-8"))
ConnectionResetError: [WinError 10054] 远程主机强迫关闭了一个现有的连接。

During handling of the above exception, another exception occurred:

Traceback (most recent call last):
  File "D:\conda\lib\site-packages\py4j\clientserver.py", line 503, in send_command
    self.socket.sendall(command.encode("utf-8"))
ConnectionResetError: [WinError 10054] 远程主机强迫关闭了一个现有的连接。

During handling of the above exception, another exception occurred:

Traceback (most recent call last):
  File "D:\conda\lib\site-packages\py4j\clientserver.py", line 503, in send_command
    self.socket.sendall(command.encode("utf-8"))
ConnectionResetError: [WinError 10054] 远程主机强迫关闭了一个现有的连接。

During handling of the above exception, another exception occurred:

Traceback (most recent call last):
  File "D:\conda\lib\site-packages\py4j\clientserver.py", line 503, in send_command
    self.socket.sendall(command.encode("utf-8"))
ConnectionResetError: [WinError 10054] 远程主机强迫关闭了一个现有的连接。

During handling of the above exception, another exception occurred:

Traceback (most recent call last):
  File "D:\conda\lib\site-packages\py4j\clientserver.py", line 503, in send_command
    self.socket.sendall(command.encode("utf-8"))
ConnectionResetError: [WinError 10054] 远程主机强迫关闭了一个现有的连接。

During handling of the above exception, another exception occurred:

Traceback (most recent call last):
  File "D:\conda\lib\site-packages\py4j\clientserver.py", line 503, in send_command
    self.socket.sendall(command.encode("utf-8"))
ConnectionResetError: [WinError 10054] 远程主机强迫关闭了一个现有的连接。

During handling of the above exception, another exception occurred:

Traceback (most recent call last):
  File "D:\conda\lib\site-packages\py4j\clientserver.py", line 503, in send_command
    self.socket.sendall(command.encode("utf-8"))
ConnectionResetError: [WinError 10054] 远程主机强迫关闭了一个现有的连接。

During handling of the above exception, another exception occurred:

Traceback (most recent call last):
  File "D:\conda\lib\site-packages\py4j\clientserver.py", line 503, in send_command
    self.socket.sendall(command.encode("utf-8"))
ConnectionResetError: [WinError 10054] 远程主机强迫关闭了一个现有的连接。

During handling of the above exception, another exception occurred:

Traceback (most recent call last):
  File "D:\conda\lib\site-packages\py4j\clientserver.py", line 503, in send_command
    self.socket.sendall(command.encode("utf-8"))
ConnectionResetError: [WinError 10054] 远程主机强迫关闭了一个现有的连接。

During handling of the above exception, another exception occurred:

Traceback (most recent call last):
  File "D:\conda\lib\site-packages\py4j\clientserver.py", line 503, in send_command
    self.socket.sendall(command.encode("utf-8"))
ConnectionResetError: [WinError 10054] 远程主机强迫关闭了一个现有的连接。

During handling of the above exception, another exception occurred:

Traceback (most recent call last):
  File "D:\conda\lib\site-packages\py4j\clientserver.py", line 503, in send_command
    self.socket.sendall(command.encode("utf-8"))
ConnectionResetError: [WinError 10054] 远程主机强迫关闭了一个现有的连接。

During handling of the above exception, another exception occurred:

Traceback (most recent call last):
  File "D:\conda\lib\site-packages\py4j\clientserver.py", line 503, in send_command
    self.socket.sendall(command.encode("utf-8"))
ConnectionResetError: [WinError 10054] 远程主机强迫关闭了一个现有的连接。

During handling of the above exception, another exception occurred:

Traceback (most recent call last):
  File "D:\conda\lib\site-packages\py4j\clientserver.py", line 503, in send_command
    self.socket.sendall(command.encode("utf-8"))
ConnectionResetError: [WinError 10054] 远程主机强迫关闭了一个现有的连接。

During handling of the above exception, another exception occurred:

Traceback (most recent call last):
  File "D:\conda\lib\site-packages\py4j\clientserver.py", line 503, in send_command
    self.socket.sendall(command.encode("utf-8"))
ConnectionResetError: [WinError 10054] 远程主机强迫关闭了一个现有的连接。

During handling of the above exception, another exception occurred:

Traceback (most recent call last):
  File "D:\conda\lib\site-packages\py4j\clientserver.py", line 503, in send_command
    self.socket.sendall(command.encode("utf-8"))
ConnectionResetError: [WinError 10054] 远程主机强迫关闭了一个现有的连接。

During handling of the above exception, another exception occurred:

Traceback (most recent call last):
  File "D:\conda\lib\site-packages\py4j\clientserver.py", line 503, in send_command
    self.socket.sendall(command.encode("utf-8"))
ConnectionResetError: [WinError 10054] 远程主机强迫关闭了一个现有的连接。

During handling of the above exception, another exception occurred:

Traceback (most recent call last):
  File "D:\conda\lib\site-packages\py4j\clientserver.py", line 503, in send_command
    self.socket.sendall(command.encode("utf-8"))
ConnectionResetError: [WinError 10054] 远程主机强迫关闭了一个现有的连接。

During handling of the above exception, another exception occurred:

Traceback (most recent call last):
  File "D:\conda\lib\site-packages\py4j\clientserver.py", line 503, in send_command
    self.socket.sendall(command.encode("utf-8"))
ConnectionResetError: [WinError 10054] 远程主机强迫关闭了一个现有的连接。

During handling of the above exception, another exception occurred:

Traceback (most recent call last):
  File "D:\conda\lib\site-packages\py4j\clientserver.py", line 503, in send_command
    self.socket.sendall(command.encode("utf-8"))
ConnectionResetError: [WinError 10054] 远程主机强迫关闭了一个现有的连接。

During handling of the above exception, another exception occurred:

Traceback (most recent call last):
  File "D:\conda\lib\site-packages\py4j\clientserver.py", line 503, in send_command
    self.socket.sendall(command.encode("utf-8"))
ConnectionResetError: [WinError 10054] 远程主机强迫关闭了一个现有的连接。

During handling of the above exception, another exception occurred:

Traceback (most recent call last):
  File "D:\conda\lib\site-packages\py4j\clientserver.py", line 503, in send_command
    self.socket.sendall(command.encode("utf-8"))
ConnectionResetError: [WinError 10054] 远程主机强迫关闭了一个现有的连接。

During handling of the above exception, another exception occurred:

Traceback (most recent call last):
  File "D:\conda\lib\site-packages\py4j\clientserver.py", line 503, in send_command
    self.socket.sendall(command.encode("utf-8"))
ConnectionResetError: [WinError 10054] 远程主机强迫关闭了一个现有的连接。

During handling of the above exception, another exception occurred:

Traceback (most recent call last):
  File "D:\conda\lib\site-packages\py4j\clientserver.py", line 503, in send_command
    self.socket.sendall(command.encode("utf-8"))
ConnectionResetError: [WinError 10054] 远程主机强迫关闭了一个现有的连接。

During handling of the above exception, another exception occurred:

Traceback (most recent call last):
  File "D:\conda\lib\site-packages\py4j\clientserver.py", line 503, in send_command
    self.socket.sendall(command.encode("utf-8"))
ConnectionResetError: [WinError 10054] 远程主机强迫关闭了一个现有的连接。

During handling of the above exception, another exception occurred:

Traceback (most recent call last):
  File "D:\conda\lib\site-packages\py4j\clientserver.py", line 503, in send_command
    self.socket.sendall(command.encode("utf-8"))
ConnectionResetError: [WinError 10054] 远程主机强迫关闭了一个现有的连接。

During handling of the above exception, another exception occurred:

Traceback (most recent call last):
  File "D:\conda\lib\site-packages\py4j\clientserver.py", line 503, in send_command
    self.socket.sendall(command.encode("utf-8"))
ConnectionResetError: [WinError 10054] 远程主机强迫关闭了一个现有的连接。

During handling of the above exception, another exception occurred:

Traceback (most recent call last):
  File "D:\conda\lib\site-packages\py4j\clientserver.py", line 503, in send_command
    self.socket.sendall(command.encode("utf-8"))
ConnectionResetError: [WinError 10054] 远程主机强迫关闭了一个现有的连接。

During handling of the above exception, another exception occurred:

Traceback (most recent call last):
  File "D:\conda\lib\site-packages\py4j\clientserver.py", line 503, in send_command
    self.socket.sendall(command.encode("utf-8"))
ConnectionResetError: [WinError 10054] 远程主机强迫关闭了一个现有的连接。

During handling of the above exception, another exception occurred:

Traceback (most recent call last):
  File "D:\conda\lib\site-packages\py4j\clientserver.py", line 503, in send_command
    self.socket.sendall(command.encode("utf-8"))
ConnectionResetError: [WinError 10054] 远程主机强迫关闭了一个现有的连接。

During handling of the above exception, another exception occurred:

Traceback (most recent call last):
  File "D:\conda\lib\site-packages\py4j\clientserver.py", line 503, in send_command
    self.socket.sendall(command.encode("utf-8"))
ConnectionResetError: [WinError 10054] 远程主机强迫关闭了一个现有的连接。

During handling of the above exception, another exception occurred:

Traceback (most recent call last):
  File "D:\conda\lib\site-packages\py4j\clientserver.py", line 503, in send_command
    self.socket.sendall(command.encode("utf-8"))
ConnectionResetError: [WinError 10054] 远程主机强迫关闭了一个现有的连接。

During handling of the above exception, another exception occurred:

Traceback (most recent call last):
  File "D:\conda\lib\site-packages\py4j\java_gateway.py", line 1038, in send_command
    response = connection.send_command(command)
  File "D:\conda\lib\site-packages\py4j\clientserver.py", line 506, in send_command
    raise Py4JNetworkError(
py4j.protocol.Py4JNetworkError: Error while sending
2025-05-16 23:51:16,654 - INFO - Closing down clientserver connection
2025-05-16 23:51:16,655 - INFO - Closing down clientserver connection
2025-05-16 23:51:12,569 - INFO - Error while sending or receiving.
Traceback (most recent call last):
  File "D:\conda\lib\site-packages\pyspark\errors\exceptions\captured.py", line 169, in deco
    return f(*a, **kw)
  File "D:\conda\lib\site-packages\py4j\protocol.py", line 326, in get_return_value
    raise Py4JJavaError(
py4j.protocol.Py4JJavaError: <exception str() failed>

During handling of the above exception, another exception occurred:

Traceback (most recent call last):
  File "D:\conda\lib\site-packages\py4j\clientserver.py", line 511, in send_command
    answer = smart_decode(self.stream.readline()[:-1])
  File "D:\conda\lib\socket.py", line 669, in readinto
    return self._sock.recv_into(b)
ConnectionResetError: [WinError 10054] 远程主机强迫关闭了一个现有的连接。

During handling of the above exception, another exception occurred:

Traceback (most recent call last):
  File "D:\conda\lib\site-packages\py4j\clientserver.py", line 503, in send_command
    self.socket.sendall(command.encode("utf-8"))
ConnectionResetError: [WinError 10054] 远程主机强迫关闭了一个现有的连接。

During handling of the above exception, another exception occurred:

Traceback (most recent call last):
  File "D:\conda\lib\site-packages\py4j\clientserver.py", line 503, in send_command
    self.socket.sendall(command.encode("utf-8"))
ConnectionResetError: [WinError 10054] 远程主机强迫关闭了一个现有的连接。

During handling of the above exception, another exception occurred:

Traceback (most recent call last):
  File "D:\conda\lib\site-packages\py4j\clientserver.py", line 503, in send_command
    self.socket.sendall(command.encode("utf-8"))
ConnectionResetError: [WinError 10054] 远程主机强迫关闭了一个现有的连接。

During handling of the above exception, another exception occurred:

Traceback (most recent call last):
  File "D:\conda\lib\site-packages\py4j\clientserver.py", line 503, in send_command
    self.socket.sendall(command.encode("utf-8"))
ConnectionResetError: [WinError 10054] 远程主机强迫关闭了一个现有的连接。

During handling of the above exception, another exception occurred:

Traceback (most recent call last):
  File "D:\conda\lib\site-packages\py4j\clientserver.py", line 503, in send_command
    self.socket.sendall(command.encode("utf-8"))
ConnectionResetError: [WinError 10054] 远程主机强迫关闭了一个现有的连接。

During handling of the above exception, another exception occurred:

Traceback (most recent call last):
  File "D:\conda\lib\site-packages\py4j\clientserver.py", line 503, in send_command
    self.socket.sendall(command.encode("utf-8"))
ConnectionResetError: [WinError 10054] 远程主机强迫关闭了一个现有的连接。

During handling of the above exception, another exception occurred:

Traceback (most recent call last):
  File "D:\conda\lib\site-packages\py4j\clientserver.py", line 503, in send_command
    self.socket.sendall(command.encode("utf-8"))
ConnectionResetError: [WinError 10054] 远程主机强迫关闭了一个现有的连接。

During handling of the above exception, another exception occurred:

Traceback (most recent call last):
  File "D:\conda\lib\site-packages\py4j\clientserver.py", line 503, in send_command
    self.socket.sendall(command.encode("utf-8"))
ConnectionResetError: [WinError 10054] 远程主机强迫关闭了一个现有的连接。

During handling of the above exception, another exception occurred:

Traceback (most recent call last):
  File "D:\conda\lib\site-packages\py4j\clientserver.py", line 503, in send_command
    self.socket.sendall(command.encode("utf-8"))
ConnectionResetError: [WinError 10054] 远程主机强迫关闭了一个现有的连接。

During handling of the above exception, another exception occurred:

Traceback (most recent call last):
  File "D:\conda\lib\site-packages\py4j\clientserver.py", line 503, in send_command
    self.socket.sendall(command.encode("utf-8"))
ConnectionResetError: [WinError 10054] 远程主机强迫关闭了一个现有的连接。

During handling of the above exception, another exception occurred:

Traceback (most recent call last):
  File "D:\conda\lib\site-packages\py4j\clientserver.py", line 503, in send_command
    self.socket.sendall(command.encode("utf-8"))
ConnectionResetError: [WinError 10054] 远程主机强迫关闭了一个现有的连接。

During handling of the above exception, another exception occurred:

Traceback (most recent call last):
  File "D:\conda\lib\site-packages\py4j\clientserver.py", line 503, in send_command
    self.socket.sendall(command.encode("utf-8"))
ConnectionResetError: [WinError 10054] 远程主机强迫关闭了一个现有的连接。

During handling of the above exception, another exception occurred:

Traceback (most recent call last):
  File "D:\conda\lib\site-packages\py4j\clientserver.py", line 503, in send_command
    self.socket.sendall(command.encode("utf-8"))
ConnectionResetError: [WinError 10054] 远程主机强迫关闭了一个现有的连接。

During handling of the above exception, another exception occurred:

Traceback (most recent call last):
  File "D:\conda\lib\site-packages\py4j\clientserver.py", line 503, in send_command
    self.socket.sendall(command.encode("utf-8"))
ConnectionResetError: [WinError 10054] 远程主机强迫关闭了一个现有的连接。

During handling of the above exception, another exception occurred:

Traceback (most recent call last):
  File "D:\conda\lib\site-packages\py4j\clientserver.py", line 503, in send_command
    self.socket.sendall(command.encode("utf-8"))
ConnectionResetError: [WinError 10054] 远程主机强迫关闭了一个现有的连接。

During handling of the above exception, another exception occurred:

Traceback (most recent call last):
  File "D:\conda\lib\site-packages\py4j\clientserver.py", line 503, in send_command
    self.socket.sendall(command.encode("utf-8"))
ConnectionResetError: [WinError 10054] 远程主机强迫关闭了一个现有的连接。

During handling of the above exception, another exception occurred:

Traceback (most recent call last):
  File "D:\conda\lib\site-packages\py4j\clientserver.py", line 503, in send_command
    self.socket.sendall(command.encode("utf-8"))
ConnectionResetError: [WinError 10054] 远程主机强迫关闭了一个现有的连接。

During handling of the above exception, another exception occurred:

Traceback (most recent call last):
  File "D:\conda\lib\site-packages\py4j\clientserver.py", line 503, in send_command
    self.socket.sendall(command.encode("utf-8"))
ConnectionResetError: [WinError 10054] 远程主机强迫关闭了一个现有的连接。

During handling of the above exception, another exception occurred:

Traceback (most recent call last):
  File "D:\conda\lib\site-packages\py4j\clientserver.py", line 503, in send_command
    self.socket.sendall(command.encode("utf-8"))
ConnectionResetError: [WinError 10054] 远程主机强迫关闭了一个现有的连接。

During handling of the above exception, another exception occurred:

Traceback (most recent call last):
  File "D:\conda\lib\site-packages\py4j\clientserver.py", line 503, in send_command
    self.socket.sendall(command.encode("utf-8"))
ConnectionResetError: [WinError 10054] 远程主机强迫关闭了一个现有的连接。

During handling of the above exception, another exception occurred:

Traceback (most recent call last):
  File "D:\conda\lib\site-packages\py4j\clientserver.py", line 503, in send_command
    self.socket.sendall(command.encode("utf-8"))
ConnectionResetError: [WinError 10054] 远程主机强迫关闭了一个现有的连接。

During handling of the above exception, another exception occurred:

Traceback (most recent call last):
  File "D:\conda\lib\site-packages\py4j\clientserver.py", line 503, in send_command
    self.socket.sendall(command.encode("utf-8"))
ConnectionResetError: [WinError 10054] 远程主机强迫关闭了一个现有的连接。

During handling of the above exception, another exception occurred:

Traceback (most recent call last):
  File "D:\conda\lib\site-packages\py4j\clientserver.py", line 503, in send_command
    self.socket.sendall(command.encode("utf-8"))
ConnectionResetError: [WinError 10054] 远程主机强迫关闭了一个现有的连接。

During handling of the above exception, another exception occurred:

Traceback (most recent call last):
  File "D:\conda\lib\site-packages\py4j\clientserver.py", line 503, in send_command
    self.socket.sendall(command.encode("utf-8"))
ConnectionResetError: [WinError 10054] 远程主机强迫关闭了一个现有的连接。

During handling of the above exception, another exception occurred:

Traceback (most recent call last):
  File "D:\conda\lib\site-packages\py4j\clientserver.py", line 503, in send_command
    self.socket.sendall(command.encode("utf-8"))
ConnectionResetError: [WinError 10054] 远程主机强迫关闭了一个现有的连接。

During handling of the above exception, another exception occurred:

Traceback (most recent call last):
  File "D:\conda\lib\site-packages\py4j\clientserver.py", line 503, in send_command
    self.socket.sendall(command.encode("utf-8"))
ConnectionResetError: [WinError 10054] 远程主机强迫关闭了一个现有的连接。

During handling of the above exception, another exception occurred:

Traceback (most recent call last):
  File "D:\conda\lib\site-packages\py4j\clientserver.py", line 503, in send_command
    self.socket.sendall(command.encode("utf-8"))
ConnectionResetError: [WinError 10054] 远程主机强迫关闭了一个现有的连接。

During handling of the above exception, another exception occurred:

Traceback (most recent call last):
  File "D:\conda\lib\site-packages\py4j\clientserver.py", line 503, in send_command
    self.socket.sendall(command.encode("utf-8"))
ConnectionResetError: [WinError 10054] 远程主机强迫关闭了一个现有的连接。

During handling of the above exception, another exception occurred:

Traceback (most recent call last):
  File "D:\conda\lib\site-packages\py4j\clientserver.py", line 503, in send_command
    self.socket.sendall(command.encode("utf-8"))
ConnectionResetError: [WinError 10054] 远程主机强迫关闭了一个现有的连接。

During handling of the above exception, another exception occurred:

Traceback (most recent call last):
  File "D:\conda\lib\site-packages\py4j\clientserver.py", line 503, in send_command
    self.socket.sendall(command.encode("utf-8"))
ConnectionResetError: [WinError 10054] 远程主机强迫关闭了一个现有的连接。

During handling of the above exception, another exception occurred:

Traceback (most recent call last):
  File "D:\conda\lib\site-packages\py4j\clientserver.py", line 503, in send_command
    self.socket.sendall(command.encode("utf-8"))
ConnectionResetError: [WinError 10054] 远程主机强迫关闭了一个现有的连接。

During handling of the above exception, another exception occurred:

Traceback (most recent call last):
  File "D:\conda\lib\site-packages\py4j\clientserver.py", line 503, in send_command
    self.socket.sendall(command.encode("utf-8"))
ConnectionResetError: [WinError 10054] 远程主机强迫关闭了一个现有的连接。

During handling of the above exception, another exception occurred:

Traceback (most recent call last):
  File "D:\conda\lib\site-packages\py4j\clientserver.py", line 503, in send_command
    self.socket.sendall(command.encode("utf-8"))
ConnectionResetError: [WinError 10054] 远程主机强迫关闭了一个现有的连接。

During handling of the above exception, another exception occurred:

Traceback (most recent call last):
  File "D:\conda\lib\site-packages\py4j\clientserver.py", line 503, in send_command
    self.socket.sendall(command.encode("utf-8"))
ConnectionResetError: [WinError 10054] 远程主机强迫关闭了一个现有的连接。

During handling of the above exception, another exception occurred:

Traceback (most recent call last):
  File "D:\conda\lib\site-packages\py4j\clientserver.py", line 503, in send_command
    self.socket.sendall(command.encode("utf-8"))
ConnectionResetError: [WinError 10054] 远程主机强迫关闭了一个现有的连接。

During handling of the above exception, another exception occurred:

Traceback (most recent call last):
  File "D:\conda\lib\site-packages\py4j\clientserver.py", line 503, in send_command
    self.socket.sendall(command.encode("utf-8"))
ConnectionResetError: [WinError 10054] 远程主机强迫关闭了一个现有的连接。

During handling of the above exception, another exception occurred:

Traceback (most recent call last):
  File "D:\conda\lib\site-packages\py4j\clientserver.py", line 503, in send_command
    self.socket.sendall(command.encode("utf-8"))
ConnectionResetError: [WinError 10054] 远程主机强迫关闭了一个现有的连接。

During handling of the above exception, another exception occurred:

Traceback (most recent call last):
  File "D:\conda\lib\site-packages\py4j\clientserver.py", line 503, in send_command
    self.socket.sendall(command.encode("utf-8"))
ConnectionResetError: [WinError 10054] 远程主机强迫关闭了一个现有的连接。

During handling of the above exception, another exception occurred:

Traceback (most recent call last):
  File "D:\conda\lib\site-packages\py4j\clientserver.py", line 503, in send_command
    self.socket.sendall(command.encode("utf-8"))
ConnectionResetError: [WinError 10054] 远程主机强迫关闭了一个现有的连接。

During handling of the above exception, another exception occurred:

Traceback (most recent call last):
  File "D:\conda\lib\site-packages\py4j\clientserver.py", line 503, in send_command
    self.socket.sendall(command.encode("utf-8"))
ConnectionResetError: [WinError 10054] 远程主机强迫关闭了一个现有的连接。

During handling of the above exception, another exception occurred:

Traceback (most recent call last):
  File "D:\conda\lib\site-packages\py4j\clientserver.py", line 503, in send_command
    self.socket.sendall(command.encode("utf-8"))
ConnectionResetError: [WinError 10054] 远程主机强迫关闭了一个现有的连接。

During handling of the above exception, another exception occurred:

Traceback (most recent call last):
  File "D:\conda\lib\site-packages\py4j\clientserver.py", line 503, in send_command
    self.socket.sendall(command.encode("utf-8"))
ConnectionResetError: [WinError 10054] 远程主机强迫关闭了一个现有的连接。

During handling of the above exception, another exception occurred:

Traceback (most recent call last):
  File "D:\conda\lib\site-packages\py4j\clientserver.py", line 503, in send_command
    self.socket.sendall(command.encode("utf-8"))
ConnectionResetError: [WinError 10054] 远程主机强迫关闭了一个现有的连接。

During handling of the above exception, another exception occurred:

Traceback (most recent call last):
  File "D:\conda\lib\site-packages\py4j\clientserver.py", line 503, in send_command
    self.socket.sendall(command.encode("utf-8"))
ConnectionResetError: [WinError 10054] 远程主机强迫关闭了一个现有的连接。
2025-05-16 23:51:16,658 - INFO - Closing down clientserver connection
2025-05-16 23:51:18,683 - INFO - Closing down clientserver connection
2025-05-16 23:51:18,684 - INFO - Closing down clientserver connection
2025-05-16 23:51:16,658 - INFO - Exception while sending command.
Traceback (most recent call last):
  File "D:\conda\lib\site-packages\pyspark\errors\exceptions\captured.py", line 169, in deco
    return f(*a, **kw)
  File "D:\conda\lib\site-packages\py4j\protocol.py", line 326, in get_return_value
    raise Py4JJavaError(
py4j.protocol.Py4JJavaError: <exception str() failed>

During handling of the above exception, another exception occurred:

Traceback (most recent call last):
  File "D:\conda\lib\site-packages\py4j\clientserver.py", line 511, in send_command
    answer = smart_decode(self.stream.readline()[:-1])
  File "D:\conda\lib\socket.py", line 669, in readinto
    return self._sock.recv_into(b)
ConnectionResetError: [WinError 10054] 远程主机强迫关闭了一个现有的连接。

During handling of the above exception, another exception occurred:

Traceback (most recent call last):
  File "D:\conda\lib\site-packages\py4j\clientserver.py", line 503, in send_command
    self.socket.sendall(command.encode("utf-8"))
ConnectionResetError: [WinError 10054] 远程主机强迫关闭了一个现有的连接。

During handling of the above exception, another exception occurred:

Traceback (most recent call last):
  File "D:\conda\lib\site-packages\py4j\clientserver.py", line 503, in send_command
    self.socket.sendall(command.encode("utf-8"))
ConnectionResetError: [WinError 10054] 远程主机强迫关闭了一个现有的连接。

During handling of the above exception, another exception occurred:

Traceback (most recent call last):
  File "D:\conda\lib\site-packages\py4j\clientserver.py", line 503, in send_command
    self.socket.sendall(command.encode("utf-8"))
ConnectionResetError: [WinError 10054] 远程主机强迫关闭了一个现有的连接。

During handling of the above exception, another exception occurred:

Traceback (most recent call last):
  File "D:\conda\lib\site-packages\py4j\clientserver.py", line 503, in send_command
    self.socket.sendall(command.encode("utf-8"))
ConnectionResetError: [WinError 10054] 远程主机强迫关闭了一个现有的连接。

During handling of the above exception, another exception occurred:

Traceback (most recent call last):
  File "D:\conda\lib\site-packages\py4j\clientserver.py", line 503, in send_command
    self.socket.sendall(command.encode("utf-8"))
ConnectionResetError: [WinError 10054] 远程主机强迫关闭了一个现有的连接。

During handling of the above exception, another exception occurred:

Traceback (most recent call last):
  File "D:\conda\lib\site-packages\py4j\clientserver.py", line 503, in send_command
    self.socket.sendall(command.encode("utf-8"))
ConnectionResetError: [WinError 10054] 远程主机强迫关闭了一个现有的连接。

During handling of the above exception, another exception occurred:

Traceback (most recent call last):
  File "D:\conda\lib\site-packages\py4j\clientserver.py", line 503, in send_command
    self.socket.sendall(command.encode("utf-8"))
ConnectionResetError: [WinError 10054] 远程主机强迫关闭了一个现有的连接。

During handling of the above exception, another exception occurred:

Traceback (most recent call last):
  File "D:\conda\lib\site-packages\py4j\clientserver.py", line 503, in send_command
    self.socket.sendall(command.encode("utf-8"))
ConnectionResetError: [WinError 10054] 远程主机强迫关闭了一个现有的连接。

During handling of the above exception, another exception occurred:

Traceback (most recent call last):
  File "D:\conda\lib\site-packages\py4j\clientserver.py", line 503, in send_command
    self.socket.sendall(command.encode("utf-8"))
ConnectionResetError: [WinError 10054] 远程主机强迫关闭了一个现有的连接。

During handling of the above exception, another exception occurred:

Traceback (most recent call last):
  File "D:\conda\lib\site-packages\py4j\clientserver.py", line 503, in send_command
    self.socket.sendall(command.encode("utf-8"))
ConnectionResetError: [WinError 10054] 远程主机强迫关闭了一个现有的连接。

During handling of the above exception, another exception occurred:

Traceback (most recent call last):
  File "D:\conda\lib\site-packages\py4j\clientserver.py", line 503, in send_command
    self.socket.sendall(command.encode("utf-8"))
ConnectionResetError: [WinError 10054] 远程主机强迫关闭了一个现有的连接。

During handling of the above exception, another exception occurred:

Traceback (most recent call last):
  File "D:\conda\lib\site-packages\py4j\clientserver.py", line 503, in send_command
    self.socket.sendall(command.encode("utf-8"))
ConnectionResetError: [WinError 10054] 远程主机强迫关闭了一个现有的连接。

During handling of the above exception, another exception occurred:

Traceback (most recent call last):
  File "D:\conda\lib\site-packages\py4j\clientserver.py", line 503, in send_command
    self.socket.sendall(command.encode("utf-8"))
ConnectionResetError: [WinError 10054] 远程主机强迫关闭了一个现有的连接。

During handling of the above exception, another exception occurred:

Traceback (most recent call last):
  File "D:\conda\lib\site-packages\py4j\clientserver.py", line 503, in send_command
    self.socket.sendall(command.encode("utf-8"))
ConnectionResetError: [WinError 10054] 远程主机强迫关闭了一个现有的连接。

During handling of the above exception, another exception occurred:

Traceback (most recent call last):
  File "D:\conda\lib\site-packages\py4j\clientserver.py", line 503, in send_command
    self.socket.sendall(command.encode("utf-8"))
ConnectionResetError: [WinError 10054] 远程主机强迫关闭了一个现有的连接。

During handling of the above exception, another exception occurred:

Traceback (most recent call last):
  File "D:\conda\lib\site-packages\py4j\clientserver.py", line 503, in send_command
    self.socket.sendall(command.encode("utf-8"))
ConnectionResetError: [WinError 10054] 远程主机强迫关闭了一个现有的连接。

During handling of the above exception, another exception occurred:

Traceback (most recent call last):
  File "D:\conda\lib\site-packages\py4j\clientserver.py", line 503, in send_command
    self.socket.sendall(command.encode("utf-8"))
ConnectionResetError: [WinError 10054] 远程主机强迫关闭了一个现有的连接。

During handling of the above exception, another exception occurred:

Traceback (most recent call last):
  File "D:\conda\lib\site-packages\py4j\clientserver.py", line 503, in send_command
    self.socket.sendall(command.encode("utf-8"))
ConnectionResetError: [WinError 10054] 远程主机强迫关闭了一个现有的连接。

During handling of the above exception, another exception occurred:

Traceback (most recent call last):
  File "D:\conda\lib\site-packages\py4j\clientserver.py", line 503, in send_command
    self.socket.sendall(command.encode("utf-8"))
ConnectionResetError: [WinError 10054] 远程主机强迫关闭了一个现有的连接。

During handling of the above exception, another exception occurred:

Traceback (most recent call last):
  File "D:\conda\lib\site-packages\py4j\clientserver.py", line 503, in send_command
    self.socket.sendall(command.encode("utf-8"))
ConnectionResetError: [WinError 10054] 远程主机强迫关闭了一个现有的连接。

During handling of the above exception, another exception occurred:

Traceback (most recent call last):
  File "D:\conda\lib\site-packages\py4j\clientserver.py", line 503, in send_command
    self.socket.sendall(command.encode("utf-8"))
ConnectionResetError: [WinError 10054] 远程主机强迫关闭了一个现有的连接。

During handling of the above exception, another exception occurred:

Traceback (most recent call last):
  File "D:\conda\lib\site-packages\py4j\clientserver.py", line 503, in send_command
    self.socket.sendall(command.encode("utf-8"))
ConnectionResetError: [WinError 10054] 远程主机强迫关闭了一个现有的连接。

During handling of the above exception, another exception occurred:

Traceback (most recent call last):
  File "D:\conda\lib\site-packages\py4j\clientserver.py", line 503, in send_command
    self.socket.sendall(command.encode("utf-8"))
ConnectionResetError: [WinError 10054] 远程主机强迫关闭了一个现有的连接。

During handling of the above exception, another exception occurred:

Traceback (most recent call last):
  File "D:\conda\lib\site-packages\py4j\clientserver.py", line 503, in send_command
    self.socket.sendall(command.encode("utf-8"))
ConnectionResetError: [WinError 10054] 远程主机强迫关闭了一个现有的连接。

During handling of the above exception, another exception occurred:

Traceback (most recent call last):
  File "D:\conda\lib\site-packages\py4j\clientserver.py", line 503, in send_command
    self.socket.sendall(command.encode("utf-8"))
ConnectionResetError: [WinError 10054] 远程主机强迫关闭了一个现有的连接。

During handling of the above exception, another exception occurred:

Traceback (most recent call last):
  File "D:\conda\lib\site-packages\py4j\clientserver.py", line 503, in send_command
    self.socket.sendall(command.encode("utf-8"))
ConnectionResetError: [WinError 10054] 远程主机强迫关闭了一个现有的连接。

During handling of the above exception, another exception occurred:

Traceback (most recent call last):
  File "D:\conda\lib\site-packages\py4j\clientserver.py", line 503, in send_command
    self.socket.sendall(command.encode("utf-8"))
ConnectionResetError: [WinError 10054] 远程主机强迫关闭了一个现有的连接。

During handling of the above exception, another exception occurred:

Traceback (most recent call last):
  File "D:\conda\lib\site-packages\py4j\clientserver.py", line 503, in send_command
    self.socket.sendall(command.encode("utf-8"))
ConnectionResetError: [WinError 10054] 远程主机强迫关闭了一个现有的连接。

During handling of the above exception, another exception occurred:

Traceback (most recent call last):
  File "D:\conda\lib\site-packages\py4j\clientserver.py", line 503, in send_command
    self.socket.sendall(command.encode("utf-8"))
ConnectionResetError: [WinError 10054] 远程主机强迫关闭了一个现有的连接。

During handling of the above exception, another exception occurred:

Traceback (most recent call last):
  File "D:\conda\lib\site-packages\py4j\clientserver.py", line 503, in send_command
    self.socket.sendall(command.encode("utf-8"))
ConnectionResetError: [WinError 10054] 远程主机强迫关闭了一个现有的连接。

During handling of the above exception, another exception occurred:

Traceback (most recent call last):
  File "D:\conda\lib\site-packages\py4j\clientserver.py", line 503, in send_command
    self.socket.sendall(command.encode("utf-8"))
ConnectionResetError: [WinError 10054] 远程主机强迫关闭了一个现有的连接。

During handling of the above exception, another exception occurred:

Traceback (most recent call last):
  File "D:\conda\lib\site-packages\py4j\clientserver.py", line 503, in send_command
    self.socket.sendall(command.encode("utf-8"))
ConnectionResetError: [WinError 10054] 远程主机强迫关闭了一个现有的连接。

During handling of the above exception, another exception occurred:

Traceback (most recent call last):
  File "D:\conda\lib\site-packages\py4j\clientserver.py", line 503, in send_command
    self.socket.sendall(command.encode("utf-8"))
ConnectionResetError: [WinError 10054] 远程主机强迫关闭了一个现有的连接。

During handling of the above exception, another exception occurred:

Traceback (most recent call last):
  File "D:\conda\lib\site-packages\py4j\clientserver.py", line 503, in send_command
    self.socket.sendall(command.encode("utf-8"))
ConnectionResetError: [WinError 10054] 远程主机强迫关闭了一个现有的连接。

During handling of the above exception, another exception occurred:

Traceback (most recent call last):
  File "D:\conda\lib\site-packages\py4j\clientserver.py", line 503, in send_command
    self.socket.sendall(command.encode("utf-8"))
ConnectionResetError: [WinError 10054] 远程主机强迫关闭了一个现有的连接。

During handling of the above exception, another exception occurred:

Traceback (most recent call last):
  File "D:\conda\lib\site-packages\py4j\clientserver.py", line 503, in send_command
    self.socket.sendall(command.encode("utf-8"))
ConnectionResetError: [WinError 10054] 远程主机强迫关闭了一个现有的连接。

During handling of the above exception, another exception occurred:

Traceback (most recent call last):
  File "D:\conda\lib\site-packages\py4j\clientserver.py", line 503, in send_command
    self.socket.sendall(command.encode("utf-8"))
ConnectionResetError: [WinError 10054] 远程主机强迫关闭了一个现有的连接。

During handling of the above exception, another exception occurred:

Traceback (most recent call last):
  File "D:\conda\lib\site-packages\py4j\clientserver.py", line 503, in send_command
    self.socket.sendall(command.encode("utf-8"))
ConnectionResetError: [WinError 10054] 远程主机强迫关闭了一个现有的连接。

During handling of the above exception, another exception occurred:

Traceback (most recent call last):
  File "D:\conda\lib\site-packages\py4j\clientserver.py", line 503, in send_command
    self.socket.sendall(command.encode("utf-8"))
ConnectionResetError: [WinError 10054] 远程主机强迫关闭了一个现有的连接。

During handling of the above exception, another exception occurred:

Traceback (most recent call last):
  File "D:\conda\lib\site-packages\py4j\clientserver.py", line 503, in send_command
    self.socket.sendall(command.encode("utf-8"))
ConnectionResetError: [WinError 10054] 远程主机强迫关闭了一个现有的连接。

During handling of the above exception, another exception occurred:

Traceback (most recent call last):
  File "D:\conda\lib\site-packages\py4j\clientserver.py", line 503, in send_command
    self.socket.sendall(command.encode("utf-8"))
ConnectionResetError: [WinError 10054] 远程主机强迫关闭了一个现有的连接。

During handling of the above exception, another exception occurred:

Traceback (most recent call last):
  File "D:\conda\lib\site-packages\py4j\clientserver.py", line 503, in send_command
    self.socket.sendall(command.encode("utf-8"))
ConnectionResetError: [WinError 10054] 远程主机强迫关闭了一个现有的连接。

During handling of the above exception, another exception occurred:

Traceback (most recent call last):
  File "D:\conda\lib\site-packages\py4j\clientserver.py", line 503, in send_command
    self.socket.sendall(command.encode("utf-8"))
ConnectionResetError: [WinError 10054] 远程主机强迫关闭了一个现有的连接。

During handling of the above exception, another exception occurred:

Traceback (most recent call last):
  File "D:\conda\lib\site-packages\py4j\clientserver.py", line 503, in send_command
    self.socket.sendall(command.encode("utf-8"))
ConnectionResetError: [WinError 10054] 远程主机强迫关闭了一个现有的连接。

During handling of the above exception, another exception occurred:

Traceback (most recent call last):
  File "D:\conda\lib\site-packages\py4j\java_gateway.py", line 1038, in send_command
    response = connection.send_command(command)
  File "D:\conda\lib\site-packages\py4j\clientserver.py", line 506, in send_command
    raise Py4JNetworkError(
py4j.protocol.Py4JNetworkError: Error while sending
2025-05-16 23:51:20,711 - INFO - Closing down clientserver connection
2025-05-16 23:51:20,711 - INFO - Closing down clientserver connection
2025-05-16 23:51:12,567 - INFO - Error while sending or receiving.
Traceback (most recent call last):
  File "D:\conda\lib\site-packages\pyspark\errors\exceptions\captured.py", line 169, in deco
    return f(*a, **kw)
  File "D:\conda\lib\site-packages\py4j\protocol.py", line 326, in get_return_value
    raise Py4JJavaError(
py4j.protocol.Py4JJavaError: <exception str() failed>

During handling of the above exception, another exception occurred:

Traceback (most recent call last):
  File "D:\conda\lib\site-packages\py4j\clientserver.py", line 511, in send_command
    answer = smart_decode(self.stream.readline()[:-1])
  File "D:\conda\lib\socket.py", line 669, in readinto
    return self._sock.recv_into(b)
ConnectionResetError: [WinError 10054] 远程主机强迫关闭了一个现有的连接。

During handling of the above exception, another exception occurred:

Traceback (most recent call last):
  File "D:\conda\lib\site-packages\py4j\clientserver.py", line 503, in send_command
    self.socket.sendall(command.encode("utf-8"))
ConnectionResetError: [WinError 10054] 远程主机强迫关闭了一个现有的连接。

During handling of the above exception, another exception occurred:

Traceback (most recent call last):
  File "D:\conda\lib\site-packages\py4j\clientserver.py", line 503, in send_command
    self.socket.sendall(command.encode("utf-8"))
ConnectionResetError: [WinError 10054] 远程主机强迫关闭了一个现有的连接。

During handling of the above exception, another exception occurred:

Traceback (most recent call last):
  File "D:\conda\lib\site-packages\py4j\clientserver.py", line 503, in send_command
    self.socket.sendall(command.encode("utf-8"))
ConnectionResetError: [WinError 10054] 远程主机强迫关闭了一个现有的连接。

During handling of the above exception, another exception occurred:

Traceback (most recent call last):
  File "D:\conda\lib\site-packages\py4j\clientserver.py", line 503, in send_command
    self.socket.sendall(command.encode("utf-8"))
ConnectionResetError: [WinError 10054] 远程主机强迫关闭了一个现有的连接。

During handling of the above exception, another exception occurred:

Traceback (most recent call last):
  File "D:\conda\lib\site-packages\py4j\clientserver.py", line 503, in send_command
    self.socket.sendall(command.encode("utf-8"))
ConnectionResetError: [WinError 10054] 远程主机强迫关闭了一个现有的连接。

During handling of the above exception, another exception occurred:

Traceback (most recent call last):
  File "D:\conda\lib\site-packages\py4j\clientserver.py", line 503, in send_command
    self.socket.sendall(command.encode("utf-8"))
ConnectionResetError: [WinError 10054] 远程主机强迫关闭了一个现有的连接。

During handling of the above exception, another exception occurred:

Traceback (most recent call last):
  File "D:\conda\lib\site-packages\py4j\clientserver.py", line 503, in send_command
    self.socket.sendall(command.encode("utf-8"))
ConnectionResetError: [WinError 10054] 远程主机强迫关闭了一个现有的连接。

During handling of the above exception, another exception occurred:

Traceback (most recent call last):
  File "D:\conda\lib\site-packages\py4j\clientserver.py", line 503, in send_command
    self.socket.sendall(command.encode("utf-8"))
ConnectionResetError: [WinError 10054] 远程主机强迫关闭了一个现有的连接。

During handling of the above exception, another exception occurred:

Traceback (most recent call last):
  File "D:\conda\lib\site-packages\py4j\clientserver.py", line 503, in send_command
    self.socket.sendall(command.encode("utf-8"))
ConnectionResetError: [WinError 10054] 远程主机强迫关闭了一个现有的连接。

During handling of the above exception, another exception occurred:

Traceback (most recent call last):
  File "D:\conda\lib\site-packages\py4j\clientserver.py", line 503, in send_command
    self.socket.sendall(command.encode("utf-8"))
ConnectionResetError: [WinError 10054] 远程主机强迫关闭了一个现有的连接。

During handling of the above exception, another exception occurred:

Traceback (most recent call last):
  File "D:\conda\lib\site-packages\py4j\clientserver.py", line 503, in send_command
    self.socket.sendall(command.encode("utf-8"))
ConnectionResetError: [WinError 10054] 远程主机强迫关闭了一个现有的连接。

During handling of the above exception, another exception occurred:

Traceback (most recent call last):
  File "D:\conda\lib\site-packages\py4j\clientserver.py", line 503, in send_command
    self.socket.sendall(command.encode("utf-8"))
ConnectionResetError: [WinError 10054] 远程主机强迫关闭了一个现有的连接。

During handling of the above exception, another exception occurred:

Traceback (most recent call last):
  File "D:\conda\lib\site-packages\py4j\clientserver.py", line 503, in send_command
    self.socket.sendall(command.encode("utf-8"))
ConnectionResetError: [WinError 10054] 远程主机强迫关闭了一个现有的连接。

During handling of the above exception, another exception occurred:

Traceback (most recent call last):
  File "D:\conda\lib\site-packages\py4j\clientserver.py", line 503, in send_command
    self.socket.sendall(command.encode("utf-8"))
ConnectionResetError: [WinError 10054] 远程主机强迫关闭了一个现有的连接。

During handling of the above exception, another exception occurred:

Traceback (most recent call last):
  File "D:\conda\lib\site-packages\py4j\clientserver.py", line 503, in send_command
    self.socket.sendall(command.encode("utf-8"))
ConnectionResetError: [WinError 10054] 远程主机强迫关闭了一个现有的连接。

During handling of the above exception, another exception occurred:

Traceback (most recent call last):
  File "D:\conda\lib\site-packages\py4j\clientserver.py", line 503, in send_command
    self.socket.sendall(command.encode("utf-8"))
ConnectionResetError: [WinError 10054] 远程主机强迫关闭了一个现有的连接。

During handling of the above exception, another exception occurred:

Traceback (most recent call last):
  File "D:\conda\lib\site-packages\py4j\clientserver.py", line 503, in send_command
    self.socket.sendall(command.encode("utf-8"))
ConnectionResetError: [WinError 10054] 远程主机强迫关闭了一个现有的连接。

During handling of the above exception, another exception occurred:

Traceback (most recent call last):
  File "D:\conda\lib\site-packages\py4j\clientserver.py", line 503, in send_command
    self.socket.sendall(command.encode("utf-8"))
ConnectionResetError: [WinError 10054] 远程主机强迫关闭了一个现有的连接。

During handling of the above exception, another exception occurred:

Traceback (most recent call last):
  File "D:\conda\lib\site-packages\py4j\clientserver.py", line 503, in send_command
    self.socket.sendall(command.encode("utf-8"))
ConnectionResetError: [WinError 10054] 远程主机强迫关闭了一个现有的连接。

During handling of the above exception, another exception occurred:

Traceback (most recent call last):
  File "D:\conda\lib\site-packages\py4j\clientserver.py", line 503, in send_command
    self.socket.sendall(command.encode("utf-8"))
ConnectionResetError: [WinError 10054] 远程主机强迫关闭了一个现有的连接。

During handling of the above exception, another exception occurred:

Traceback (most recent call last):
  File "D:\conda\lib\site-packages\py4j\clientserver.py", line 503, in send_command
    self.socket.sendall(command.encode("utf-8"))
ConnectionResetError: [WinError 10054] 远程主机强迫关闭了一个现有的连接。

During handling of the above exception, another exception occurred:

Traceback (most recent call last):
  File "D:\conda\lib\site-packages\py4j\clientserver.py", line 503, in send_command
    self.socket.sendall(command.encode("utf-8"))
ConnectionResetError: [WinError 10054] 远程主机强迫关闭了一个现有的连接。

During handling of the above exception, another exception occurred:

Traceback (most recent call last):
  File "D:\conda\lib\site-packages\py4j\clientserver.py", line 503, in send_command
    self.socket.sendall(command.encode("utf-8"))
ConnectionResetError: [WinError 10054] 远程主机强迫关闭了一个现有的连接。

During handling of the above exception, another exception occurred:

Traceback (most recent call last):
  File "D:\conda\lib\site-packages\py4j\clientserver.py", line 503, in send_command
    self.socket.sendall(command.encode("utf-8"))
ConnectionResetError: [WinError 10054] 远程主机强迫关闭了一个现有的连接。

During handling of the above exception, another exception occurred:

Traceback (most recent call last):
  File "D:\conda\lib\site-packages\py4j\clientserver.py", line 503, in send_command
    self.socket.sendall(command.encode("utf-8"))
ConnectionResetError: [WinError 10054] 远程主机强迫关闭了一个现有的连接。

During handling of the above exception, another exception occurred:

Traceback (most recent call last):
  File "D:\conda\lib\site-packages\py4j\clientserver.py", line 503, in send_command
    self.socket.sendall(command.encode("utf-8"))
ConnectionResetError: [WinError 10054] 远程主机强迫关闭了一个现有的连接。

During handling of the above exception, another exception occurred:

Traceback (most recent call last):
  File "D:\conda\lib\site-packages\py4j\clientserver.py", line 503, in send_command
    self.socket.sendall(command.encode("utf-8"))
ConnectionResetError: [WinError 10054] 远程主机强迫关闭了一个现有的连接。

During handling of the above exception, another exception occurred:

Traceback (most recent call last):
  File "D:\conda\lib\site-packages\py4j\clientserver.py", line 503, in send_command
    self.socket.sendall(command.encode("utf-8"))
ConnectionResetError: [WinError 10054] 远程主机强迫关闭了一个现有的连接。

During handling of the above exception, another exception occurred:

Traceback (most recent call last):
  File "D:\conda\lib\site-packages\py4j\clientserver.py", line 503, in send_command
    self.socket.sendall(command.encode("utf-8"))
ConnectionResetError: [WinError 10054] 远程主机强迫关闭了一个现有的连接。

During handling of the above exception, another exception occurred:

Traceback (most recent call last):
  File "D:\conda\lib\site-packages\py4j\clientserver.py", line 503, in send_command
    self.socket.sendall(command.encode("utf-8"))
ConnectionResetError: [WinError 10054] 远程主机强迫关闭了一个现有的连接。

During handling of the above exception, another exception occurred:

Traceback (most recent call last):
  File "D:\conda\lib\site-packages\py4j\clientserver.py", line 503, in send_command
    self.socket.sendall(command.encode("utf-8"))
ConnectionResetError: [WinError 10054] 远程主机强迫关闭了一个现有的连接。

During handling of the above exception, another exception occurred:

Traceback (most recent call last):
  File "D:\conda\lib\site-packages\py4j\clientserver.py", line 503, in send_command
    self.socket.sendall(command.encode("utf-8"))
ConnectionResetError: [WinError 10054] 远程主机强迫关闭了一个现有的连接。

During handling of the above exception, another exception occurred:

Traceback (most recent call last):
  File "D:\conda\lib\site-packages\py4j\clientserver.py", line 503, in send_command
    self.socket.sendall(command.encode("utf-8"))
ConnectionResetError: [WinError 10054] 远程主机强迫关闭了一个现有的连接。

During handling of the above exception, another exception occurred:

Traceback (most recent call last):
  File "D:\conda\lib\site-packages\py4j\clientserver.py", line 503, in send_command
    self.socket.sendall(command.encode("utf-8"))
ConnectionResetError: [WinError 10054] 远程主机强迫关闭了一个现有的连接。

During handling of the above exception, another exception occurred:

Traceback (most recent call last):
  File "D:\conda\lib\site-packages\py4j\clientserver.py", line 503, in send_command
    self.socket.sendall(command.encode("utf-8"))
ConnectionResetError: [WinError 10054] 远程主机强迫关闭了一个现有的连接。

During handling of the above exception, another exception occurred:

Traceback (most recent call last):
  File "D:\conda\lib\site-packages\py4j\clientserver.py", line 503, in send_command
    self.socket.sendall(command.encode("utf-8"))
ConnectionResetError: [WinError 10054] 远程主机强迫关闭了一个现有的连接。

During handling of the above exception, another exception occurred:

Traceback (most recent call last):
  File "D:\conda\lib\site-packages\py4j\clientserver.py", line 503, in send_command
    self.socket.sendall(command.encode("utf-8"))
ConnectionResetError: [WinError 10054] 远程主机强迫关闭了一个现有的连接。

During handling of the above exception, another exception occurred:

Traceback (most recent call last):
  File "D:\conda\lib\site-packages\py4j\clientserver.py", line 503, in send_command
    self.socket.sendall(command.encode("utf-8"))
ConnectionResetError: [WinError 10054] 远程主机强迫关闭了一个现有的连接。

During handling of the above exception, another exception occurred:

Traceback (most recent call last):
  File "D:\conda\lib\site-packages\py4j\clientserver.py", line 503, in send_command
    self.socket.sendall(command.encode("utf-8"))
ConnectionResetError: [WinError 10054] 远程主机强迫关闭了一个现有的连接。

During handling of the above exception, another exception occurred:

Traceback (most recent call last):
  File "D:\conda\lib\site-packages\py4j\clientserver.py", line 503, in send_command
    self.socket.sendall(command.encode("utf-8"))
ConnectionResetError: [WinError 10054] 远程主机强迫关闭了一个现有的连接。

During handling of the above exception, another exception occurred:

Traceback (most recent call last):
  File "D:\conda\lib\site-packages\py4j\clientserver.py", line 503, in send_command
    self.socket.sendall(command.encode("utf-8"))
ConnectionResetError: [WinError 10054] 远程主机强迫关闭了一个现有的连接。

During handling of the above exception, another exception occurred:

Traceback (most recent call last):
  File "D:\conda\lib\site-packages\py4j\clientserver.py", line 503, in send_command
    self.socket.sendall(command.encode("utf-8"))
ConnectionResetError: [WinError 10054] 远程主机强迫关闭了一个现有的连接。

During handling of the above exception, another exception occurred:

Traceback (most recent call last):
  File "D:\conda\lib\site-packages\py4j\clientserver.py", line 503, in send_command
    self.socket.sendall(command.encode("utf-8"))
ConnectionResetError: [WinError 10054] 远程主机强迫关闭了一个现有的连接。
2025-05-16 23:51:20,716 - INFO - Closing down clientserver connection
2025-05-16 23:51:22,768 - INFO - Closing down clientserver connection
2025-05-16 23:51:22,768 - INFO - Closing down clientserver connection
2025-05-16 23:51:20,716 - INFO - Exception while sending command.
Traceback (most recent call last):
  File "D:\conda\lib\site-packages\pyspark\errors\exceptions\captured.py", line 169, in deco
    return f(*a, **kw)
  File "D:\conda\lib\site-packages\py4j\protocol.py", line 326, in get_return_value
    raise Py4JJavaError(
py4j.protocol.Py4JJavaError: <exception str() failed>

During handling of the above exception, another exception occurred:

Traceback (most recent call last):
  File "D:\conda\lib\site-packages\py4j\clientserver.py", line 511, in send_command
    answer = smart_decode(self.stream.readline()[:-1])
  File "D:\conda\lib\socket.py", line 669, in readinto
    return self._sock.recv_into(b)
ConnectionResetError: [WinError 10054] 远程主机强迫关闭了一个现有的连接。

During handling of the above exception, another exception occurred:

Traceback (most recent call last):
  File "D:\conda\lib\site-packages\py4j\clientserver.py", line 503, in send_command
    self.socket.sendall(command.encode("utf-8"))
ConnectionResetError: [WinError 10054] 远程主机强迫关闭了一个现有的连接。

During handling of the above exception, another exception occurred:

Traceback (most recent call last):
  File "D:\conda\lib\site-packages\py4j\clientserver.py", line 503, in send_command
    self.socket.sendall(command.encode("utf-8"))
ConnectionResetError: [WinError 10054] 远程主机强迫关闭了一个现有的连接。

During handling of the above exception, another exception occurred:

Traceback (most recent call last):
  File "D:\conda\lib\site-packages\py4j\clientserver.py", line 503, in send_command
    self.socket.sendall(command.encode("utf-8"))
ConnectionResetError: [WinError 10054] 远程主机强迫关闭了一个现有的连接。

During handling of the above exception, another exception occurred:

Traceback (most recent call last):
  File "D:\conda\lib\site-packages\py4j\clientserver.py", line 503, in send_command
    self.socket.sendall(command.encode("utf-8"))
ConnectionResetError: [WinError 10054] 远程主机强迫关闭了一个现有的连接。

During handling of the above exception, another exception occurred:

Traceback (most recent call last):
  File "D:\conda\lib\site-packages\py4j\clientserver.py", line 503, in send_command
    self.socket.sendall(command.encode("utf-8"))
ConnectionResetError: [WinError 10054] 远程主机强迫关闭了一个现有的连接。

During handling of the above exception, another exception occurred:

Traceback (most recent call last):
  File "D:\conda\lib\site-packages\py4j\clientserver.py", line 503, in send_command
    self.socket.sendall(command.encode("utf-8"))
ConnectionResetError: [WinError 10054] 远程主机强迫关闭了一个现有的连接。

During handling of the above exception, another exception occurred:

Traceback (most recent call last):
  File "D:\conda\lib\site-packages\py4j\clientserver.py", line 503, in send_command
    self.socket.sendall(command.encode("utf-8"))
ConnectionResetError: [WinError 10054] 远程主机强迫关闭了一个现有的连接。

During handling of the above exception, another exception occurred:

Traceback (most recent call last):
  File "D:\conda\lib\site-packages\py4j\clientserver.py", line 503, in send_command
    self.socket.sendall(command.encode("utf-8"))
ConnectionResetError: [WinError 10054] 远程主机强迫关闭了一个现有的连接。

During handling of the above exception, another exception occurred:

Traceback (most recent call last):
  File "D:\conda\lib\site-packages\py4j\clientserver.py", line 503, in send_command
    self.socket.sendall(command.encode("utf-8"))
ConnectionResetError: [WinError 10054] 远程主机强迫关闭了一个现有的连接。

During handling of the above exception, another exception occurred:

Traceback (most recent call last):
  File "D:\conda\lib\site-packages\py4j\clientserver.py", line 503, in send_command
    self.socket.sendall(command.encode("utf-8"))
ConnectionResetError: [WinError 10054] 远程主机强迫关闭了一个现有的连接。

During handling of the above exception, another exception occurred:

Traceback (most recent call last):
  File "D:\conda\lib\site-packages\py4j\clientserver.py", line 503, in send_command
    self.socket.sendall(command.encode("utf-8"))
ConnectionResetError: [WinError 10054] 远程主机强迫关闭了一个现有的连接。

During handling of the above exception, another exception occurred:

Traceback (most recent call last):
  File "D:\conda\lib\site-packages\py4j\clientserver.py", line 503, in send_command
    self.socket.sendall(command.encode("utf-8"))
ConnectionResetError: [WinError 10054] 远程主机强迫关闭了一个现有的连接。

During handling of the above exception, another exception occurred:

Traceback (most recent call last):
  File "D:\conda\lib\site-packages\py4j\clientserver.py", line 503, in send_command
    self.socket.sendall(command.encode("utf-8"))
ConnectionResetError: [WinError 10054] 远程主机强迫关闭了一个现有的连接。

During handling of the above exception, another exception occurred:

Traceback (most recent call last):
  File "D:\conda\lib\site-packages\py4j\clientserver.py", line 503, in send_command
    self.socket.sendall(command.encode("utf-8"))
ConnectionResetError: [WinError 10054] 远程主机强迫关闭了一个现有的连接。

During handling of the above exception, another exception occurred:

Traceback (most recent call last):
  File "D:\conda\lib\site-packages\py4j\clientserver.py", line 503, in send_command
    self.socket.sendall(command.encode("utf-8"))
ConnectionResetError: [WinError 10054] 远程主机强迫关闭了一个现有的连接。

During handling of the above exception, another exception occurred:

Traceback (most recent call last):
  File "D:\conda\lib\site-packages\py4j\clientserver.py", line 503, in send_command
    self.socket.sendall(command.encode("utf-8"))
ConnectionResetError: [WinError 10054] 远程主机强迫关闭了一个现有的连接。

During handling of the above exception, another exception occurred:

Traceback (most recent call last):
  File "D:\conda\lib\site-packages\py4j\clientserver.py", line 503, in send_command
    self.socket.sendall(command.encode("utf-8"))
ConnectionResetError: [WinError 10054] 远程主机强迫关闭了一个现有的连接。

During handling of the above exception, another exception occurred:

Traceback (most recent call last):
  File "D:\conda\lib\site-packages\py4j\clientserver.py", line 503, in send_command
    self.socket.sendall(command.encode("utf-8"))
ConnectionResetError: [WinError 10054] 远程主机强迫关闭了一个现有的连接。

During handling of the above exception, another exception occurred:

Traceback (most recent call last):
  File "D:\conda\lib\site-packages\py4j\clientserver.py", line 503, in send_command
    self.socket.sendall(command.encode("utf-8"))
ConnectionResetError: [WinError 10054] 远程主机强迫关闭了一个现有的连接。

During handling of the above exception, another exception occurred:

Traceback (most recent call last):
  File "D:\conda\lib\site-packages\py4j\clientserver.py", line 503, in send_command
    self.socket.sendall(command.encode("utf-8"))
ConnectionResetError: [WinError 10054] 远程主机强迫关闭了一个现有的连接。

During handling of the above exception, another exception occurred:

Traceback (most recent call last):
  File "D:\conda\lib\site-packages\py4j\clientserver.py", line 503, in send_command
    self.socket.sendall(command.encode("utf-8"))
ConnectionResetError: [WinError 10054] 远程主机强迫关闭了一个现有的连接。

During handling of the above exception, another exception occurred:

Traceback (most recent call last):
  File "D:\conda\lib\site-packages\py4j\clientserver.py", line 503, in send_command
    self.socket.sendall(command.encode("utf-8"))
ConnectionResetError: [WinError 10054] 远程主机强迫关闭了一个现有的连接。

During handling of the above exception, another exception occurred:

Traceback (most recent call last):
  File "D:\conda\lib\site-packages\py4j\clientserver.py", line 503, in send_command
    self.socket.sendall(command.encode("utf-8"))
ConnectionResetError: [WinError 10054] 远程主机强迫关闭了一个现有的连接。

During handling of the above exception, another exception occurred:

Traceback (most recent call last):
  File "D:\conda\lib\site-packages\py4j\clientserver.py", line 503, in send_command
    self.socket.sendall(command.encode("utf-8"))
ConnectionResetError: [WinError 10054] 远程主机强迫关闭了一个现有的连接。

During handling of the above exception, another exception occurred:

Traceback (most recent call last):
  File "D:\conda\lib\site-packages\py4j\clientserver.py", line 503, in send_command
    self.socket.sendall(command.encode("utf-8"))
ConnectionResetError: [WinError 10054] 远程主机强迫关闭了一个现有的连接。

During handling of the above exception, another exception occurred:

Traceback (most recent call last):
  File "D:\conda\lib\site-packages\py4j\clientserver.py", line 503, in send_command
    self.socket.sendall(command.encode("utf-8"))
ConnectionResetError: [WinError 10054] 远程主机强迫关闭了一个现有的连接。

During handling of the above exception, another exception occurred:

Traceback (most recent call last):
  File "D:\conda\lib\site-packages\py4j\clientserver.py", line 503, in send_command
    self.socket.sendall(command.encode("utf-8"))
ConnectionResetError: [WinError 10054] 远程主机强迫关闭了一个现有的连接。

During handling of the above exception, another exception occurred:

Traceback (most recent call last):
  File "D:\conda\lib\site-packages\py4j\clientserver.py", line 503, in send_command
    self.socket.sendall(command.encode("utf-8"))
ConnectionResetError: [WinError 10054] 远程主机强迫关闭了一个现有的连接。

During handling of the above exception, another exception occurred:

Traceback (most recent call last):
  File "D:\conda\lib\site-packages\py4j\clientserver.py", line 503, in send_command
    self.socket.sendall(command.encode("utf-8"))
ConnectionResetError: [WinError 10054] 远程主机强迫关闭了一个现有的连接。

During handling of the above exception, another exception occurred:

Traceback (most recent call last):
  File "D:\conda\lib\site-packages\py4j\clientserver.py", line 503, in send_command
    self.socket.sendall(command.encode("utf-8"))
ConnectionResetError: [WinError 10054] 远程主机强迫关闭了一个现有的连接。

During handling of the above exception, another exception occurred:

Traceback (most recent call last):
  File "D:\conda\lib\site-packages\py4j\clientserver.py", line 503, in send_command
    self.socket.sendall(command.encode("utf-8"))
ConnectionResetError: [WinError 10054] 远程主机强迫关闭了一个现有的连接。

During handling of the above exception, another exception occurred:

Traceback (most recent call last):
  File "D:\conda\lib\site-packages\py4j\clientserver.py", line 503, in send_command
    self.socket.sendall(command.encode("utf-8"))
ConnectionResetError: [WinError 10054] 远程主机强迫关闭了一个现有的连接。

During handling of the above exception, another exception occurred:

Traceback (most recent call last):
  File "D:\conda\lib\site-packages\py4j\clientserver.py", line 503, in send_command
    self.socket.sendall(command.encode("utf-8"))
ConnectionResetError: [WinError 10054] 远程主机强迫关闭了一个现有的连接。

During handling of the above exception, another exception occurred:

Traceback (most recent call last):
  File "D:\conda\lib\site-packages\py4j\clientserver.py", line 503, in send_command
    self.socket.sendall(command.encode("utf-8"))
ConnectionResetError: [WinError 10054] 远程主机强迫关闭了一个现有的连接。

During handling of the above exception, another exception occurred:

Traceback (most recent call last):
  File "D:\conda\lib\site-packages\py4j\clientserver.py", line 503, in send_command
    self.socket.sendall(command.encode("utf-8"))
ConnectionResetError: [WinError 10054] 远程主机强迫关闭了一个现有的连接。

During handling of the above exception, another exception occurred:

Traceback (most recent call last):
  File "D:\conda\lib\site-packages\py4j\clientserver.py", line 503, in send_command
    self.socket.sendall(command.encode("utf-8"))
ConnectionResetError: [WinError 10054] 远程主机强迫关闭了一个现有的连接。

During handling of the above exception, another exception occurred:

Traceback (most recent call last):
  File "D:\conda\lib\site-packages\py4j\clientserver.py", line 503, in send_command
    self.socket.sendall(command.encode("utf-8"))
ConnectionResetError: [WinError 10054] 远程主机强迫关闭了一个现有的连接。

During handling of the above exception, another exception occurred:

Traceback (most recent call last):
  File "D:\conda\lib\site-packages\py4j\clientserver.py", line 503, in send_command
    self.socket.sendall(command.encode("utf-8"))
ConnectionResetError: [WinError 10054] 远程主机强迫关闭了一个现有的连接。

During handling of the above exception, another exception occurred:

Traceback (most recent call last):
  File "D:\conda\lib\site-packages\py4j\clientserver.py", line 503, in send_command
    self.socket.sendall(command.encode("utf-8"))
ConnectionResetError: [WinError 10054] 远程主机强迫关闭了一个现有的连接。

During handling of the above exception, another exception occurred:

Traceback (most recent call last):
  File "D:\conda\lib\site-packages\py4j\clientserver.py", line 503, in send_command
    self.socket.sendall(command.encode("utf-8"))
ConnectionResetError: [WinError 10054] 远程主机强迫关闭了一个现有的连接。

During handling of the above exception, another exception occurred:

Traceback (most recent call last):
  File "D:\conda\lib\site-packages\py4j\clientserver.py", line 503, in send_command
    self.socket.sendall(command.encode("utf-8"))
ConnectionResetError: [WinError 10054] 远程主机强迫关闭了一个现有的连接。

During handling of the above exception, another exception occurred:

Traceback (most recent call last):
  File "D:\conda\lib\site-packages\py4j\clientserver.py", line 503, in send_command
    self.socket.sendall(command.encode("utf-8"))
ConnectionResetError: [WinError 10054] 远程主机强迫关闭了一个现有的连接。

During handling of the above exception, another exception occurred:

Traceback (most recent call last):
  File "D:\conda\lib\site-packages\py4j\clientserver.py", line 503, in send_command
    self.socket.sendall(command.encode("utf-8"))
ConnectionResetError: [WinError 10054] 远程主机强迫关闭了一个现有的连接。

During handling of the above exception, another exception occurred:

Traceback (most recent call last):
  File "D:\conda\lib\site-packages\py4j\java_gateway.py", line 1038, in send_command
    response = connection.send_command(command)
  File "D:\conda\lib\site-packages\py4j\clientserver.py", line 506, in send_command
    raise Py4JNetworkError(
py4j.protocol.Py4JNetworkError: Error while sending
2025-05-16 23:51:24,816 - INFO - Closing down clientserver connection
2025-05-16 23:51:24,817 - INFO - Closing down clientserver connection
2025-05-16 23:51:12,564 - INFO - Error while sending or receiving.
Traceback (most recent call last):
  File "D:\conda\lib\site-packages\pyspark\errors\exceptions\captured.py", line 169, in deco
    return f(*a, **kw)
  File "D:\conda\lib\site-packages\py4j\protocol.py", line 326, in get_return_value
    raise Py4JJavaError(
py4j.protocol.Py4JJavaError: <exception str() failed>

During handling of the above exception, another exception occurred:

Traceback (most recent call last):
  File "D:\conda\lib\site-packages\py4j\clientserver.py", line 511, in send_command
    answer = smart_decode(self.stream.readline()[:-1])
  File "D:\conda\lib\socket.py", line 669, in readinto
    return self._sock.recv_into(b)
ConnectionResetError: [WinError 10054] 远程主机强迫关闭了一个现有的连接。

During handling of the above exception, another exception occurred:

Traceback (most recent call last):
  File "D:\conda\lib\site-packages\py4j\clientserver.py", line 503, in send_command
    self.socket.sendall(command.encode("utf-8"))
ConnectionResetError: [WinError 10054] 远程主机强迫关闭了一个现有的连接。

During handling of the above exception, another exception occurred:

Traceback (most recent call last):
  File "D:\conda\lib\site-packages\py4j\clientserver.py", line 503, in send_command
    self.socket.sendall(command.encode("utf-8"))
ConnectionResetError: [WinError 10054] 远程主机强迫关闭了一个现有的连接。

During handling of the above exception, another exception occurred:

Traceback (most recent call last):
  File "D:\conda\lib\site-packages\py4j\clientserver.py", line 503, in send_command
    self.socket.sendall(command.encode("utf-8"))
ConnectionResetError: [WinError 10054] 远程主机强迫关闭了一个现有的连接。

During handling of the above exception, another exception occurred:

Traceback (most recent call last):
  File "D:\conda\lib\site-packages\py4j\clientserver.py", line 503, in send_command
    self.socket.sendall(command.encode("utf-8"))
ConnectionResetError: [WinError 10054] 远程主机强迫关闭了一个现有的连接。

During handling of the above exception, another exception occurred:

Traceback (most recent call last):
  File "D:\conda\lib\site-packages\py4j\clientserver.py", line 503, in send_command
    self.socket.sendall(command.encode("utf-8"))
ConnectionResetError: [WinError 10054] 远程主机强迫关闭了一个现有的连接。

During handling of the above exception, another exception occurred:

Traceback (most recent call last):
  File "D:\conda\lib\site-packages\py4j\clientserver.py", line 503, in send_command
    self.socket.sendall(command.encode("utf-8"))
ConnectionResetError: [WinError 10054] 远程主机强迫关闭了一个现有的连接。

During handling of the above exception, another exception occurred:

Traceback (most recent call last):
  File "D:\conda\lib\site-packages\py4j\clientserver.py", line 503, in send_command
    self.socket.sendall(command.encode("utf-8"))
ConnectionResetError: [WinError 10054] 远程主机强迫关闭了一个现有的连接。

During handling of the above exception, another exception occurred:

Traceback (most recent call last):
  File "D:\conda\lib\site-packages\py4j\clientserver.py", line 503, in send_command
    self.socket.sendall(command.encode("utf-8"))
ConnectionResetError: [WinError 10054] 远程主机强迫关闭了一个现有的连接。

During handling of the above exception, another exception occurred:

Traceback (most recent call last):
  File "D:\conda\lib\site-packages\py4j\clientserver.py", line 503, in send_command
    self.socket.sendall(command.encode("utf-8"))
ConnectionResetError: [WinError 10054] 远程主机强迫关闭了一个现有的连接。

During handling of the above exception, another exception occurred:

Traceback (most recent call last):
  File "D:\conda\lib\site-packages\py4j\clientserver.py", line 503, in send_command
    self.socket.sendall(command.encode("utf-8"))
ConnectionResetError: [WinError 10054] 远程主机强迫关闭了一个现有的连接。

During handling of the above exception, another exception occurred:

Traceback (most recent call last):
  File "D:\conda\lib\site-packages\py4j\clientserver.py", line 503, in send_command
    self.socket.sendall(command.encode("utf-8"))
ConnectionResetError: [WinError 10054] 远程主机强迫关闭了一个现有的连接。

During handling of the above exception, another exception occurred:

Traceback (most recent call last):
  File "D:\conda\lib\site-packages\py4j\clientserver.py", line 503, in send_command
    self.socket.sendall(command.encode("utf-8"))
ConnectionResetError: [WinError 10054] 远程主机强迫关闭了一个现有的连接。

During handling of the above exception, another exception occurred:

Traceback (most recent call last):
  File "D:\conda\lib\site-packages\py4j\clientserver.py", line 503, in send_command
    self.socket.sendall(command.encode("utf-8"))
ConnectionResetError: [WinError 10054] 远程主机强迫关闭了一个现有的连接。

During handling of the above exception, another exception occurred:

Traceback (most recent call last):
  File "D:\conda\lib\site-packages\py4j\clientserver.py", line 503, in send_command
    self.socket.sendall(command.encode("utf-8"))
ConnectionResetError: [WinError 10054] 远程主机强迫关闭了一个现有的连接。

During handling of the above exception, another exception occurred:

Traceback (most recent call last):
  File "D:\conda\lib\site-packages\py4j\clientserver.py", line 503, in send_command
    self.socket.sendall(command.encode("utf-8"))
ConnectionResetError: [WinError 10054] 远程主机强迫关闭了一个现有的连接。

During handling of the above exception, another exception occurred:

Traceback (most recent call last):
  File "D:\conda\lib\site-packages\py4j\clientserver.py", line 503, in send_command
    self.socket.sendall(command.encode("utf-8"))
ConnectionResetError: [WinError 10054] 远程主机强迫关闭了一个现有的连接。

During handling of the above exception, another exception occurred:

Traceback (most recent call last):
  File "D:\conda\lib\site-packages\py4j\clientserver.py", line 503, in send_command
    self.socket.sendall(command.encode("utf-8"))
ConnectionResetError: [WinError 10054] 远程主机强迫关闭了一个现有的连接。

During handling of the above exception, another exception occurred:

Traceback (most recent call last):
  File "D:\conda\lib\site-packages\py4j\clientserver.py", line 503, in send_command
    self.socket.sendall(command.encode("utf-8"))
ConnectionResetError: [WinError 10054] 远程主机强迫关闭了一个现有的连接。

During handling of the above exception, another exception occurred:

Traceback (most recent call last):
  File "D:\conda\lib\site-packages\py4j\clientserver.py", line 503, in send_command
    self.socket.sendall(command.encode("utf-8"))
ConnectionResetError: [WinError 10054] 远程主机强迫关闭了一个现有的连接。

During handling of the above exception, another exception occurred:

Traceback (most recent call last):
  File "D:\conda\lib\site-packages\py4j\clientserver.py", line 503, in send_command
    self.socket.sendall(command.encode("utf-8"))
ConnectionResetError: [WinError 10054] 远程主机强迫关闭了一个现有的连接。

During handling of the above exception, another exception occurred:

Traceback (most recent call last):
  File "D:\conda\lib\site-packages\py4j\clientserver.py", line 503, in send_command
    self.socket.sendall(command.encode("utf-8"))
ConnectionResetError: [WinError 10054] 远程主机强迫关闭了一个现有的连接。

During handling of the above exception, another exception occurred:

Traceback (most recent call last):
  File "D:\conda\lib\site-packages\py4j\clientserver.py", line 503, in send_command
    self.socket.sendall(command.encode("utf-8"))
ConnectionResetError: [WinError 10054] 远程主机强迫关闭了一个现有的连接。

During handling of the above exception, another exception occurred:

Traceback (most recent call last):
  File "D:\conda\lib\site-packages\py4j\clientserver.py", line 503, in send_command
    self.socket.sendall(command.encode("utf-8"))
ConnectionResetError: [WinError 10054] 远程主机强迫关闭了一个现有的连接。

During handling of the above exception, another exception occurred:

Traceback (most recent call last):
  File "D:\conda\lib\site-packages\py4j\clientserver.py", line 503, in send_command
    self.socket.sendall(command.encode("utf-8"))
ConnectionResetError: [WinError 10054] 远程主机强迫关闭了一个现有的连接。

During handling of the above exception, another exception occurred:

Traceback (most recent call last):
  File "D:\conda\lib\site-packages\py4j\clientserver.py", line 503, in send_command
    self.socket.sendall(command.encode("utf-8"))
ConnectionResetError: [WinError 10054] 远程主机强迫关闭了一个现有的连接。

During handling of the above exception, another exception occurred:

Traceback (most recent call last):
  File "D:\conda\lib\site-packages\py4j\clientserver.py", line 503, in send_command
    self.socket.sendall(command.encode("utf-8"))
ConnectionResetError: [WinError 10054] 远程主机强迫关闭了一个现有的连接。

During handling of the above exception, another exception occurred:

Traceback (most recent call last):
  File "D:\conda\lib\site-packages\py4j\clientserver.py", line 503, in send_command
    self.socket.sendall(command.encode("utf-8"))
ConnectionResetError: [WinError 10054] 远程主机强迫关闭了一个现有的连接。

During handling of the above exception, another exception occurred:

Traceback (most recent call last):
  File "D:\conda\lib\site-packages\py4j\clientserver.py", line 503, in send_command
    self.socket.sendall(command.encode("utf-8"))
ConnectionResetError: [WinError 10054] 远程主机强迫关闭了一个现有的连接。

During handling of the above exception, another exception occurred:

Traceback (most recent call last):
  File "D:\conda\lib\site-packages\py4j\clientserver.py", line 503, in send_command
    self.socket.sendall(command.encode("utf-8"))
ConnectionResetError: [WinError 10054] 远程主机强迫关闭了一个现有的连接。

During handling of the above exception, another exception occurred:

Traceback (most recent call last):
  File "D:\conda\lib\site-packages\py4j\clientserver.py", line 503, in send_command
    self.socket.sendall(command.encode("utf-8"))
ConnectionResetError: [WinError 10054] 远程主机强迫关闭了一个现有的连接。

During handling of the above exception, another exception occurred:

Traceback (most recent call last):
  File "D:\conda\lib\site-packages\py4j\clientserver.py", line 503, in send_command
    self.socket.sendall(command.encode("utf-8"))
ConnectionResetError: [WinError 10054] 远程主机强迫关闭了一个现有的连接。

During handling of the above exception, another exception occurred:

Traceback (most recent call last):
  File "D:\conda\lib\site-packages\py4j\clientserver.py", line 503, in send_command
    self.socket.sendall(command.encode("utf-8"))
ConnectionResetError: [WinError 10054] 远程主机强迫关闭了一个现有的连接。

During handling of the above exception, another exception occurred:

Traceback (most recent call last):
  File "D:\conda\lib\site-packages\py4j\clientserver.py", line 503, in send_command
    self.socket.sendall(command.encode("utf-8"))
ConnectionResetError: [WinError 10054] 远程主机强迫关闭了一个现有的连接。

During handling of the above exception, another exception occurred:

Traceback (most recent call last):
  File "D:\conda\lib\site-packages\py4j\clientserver.py", line 503, in send_command
    self.socket.sendall(command.encode("utf-8"))
ConnectionResetError: [WinError 10054] 远程主机强迫关闭了一个现有的连接。

During handling of the above exception, another exception occurred:

Traceback (most recent call last):
  File "D:\conda\lib\site-packages\py4j\clientserver.py", line 503, in send_command
    self.socket.sendall(command.encode("utf-8"))
ConnectionResetError: [WinError 10054] 远程主机强迫关闭了一个现有的连接。

During handling of the above exception, another exception occurred:

Traceback (most recent call last):
  File "D:\conda\lib\site-packages\py4j\clientserver.py", line 503, in send_command
    self.socket.sendall(command.encode("utf-8"))
ConnectionResetError: [WinError 10054] 远程主机强迫关闭了一个现有的连接。

During handling of the above exception, another exception occurred:

Traceback (most recent call last):
  File "D:\conda\lib\site-packages\py4j\clientserver.py", line 503, in send_command
    self.socket.sendall(command.encode("utf-8"))
ConnectionResetError: [WinError 10054] 远程主机强迫关闭了一个现有的连接。

During handling of the above exception, another exception occurred:

Traceback (most recent call last):
  File "D:\conda\lib\site-packages\py4j\clientserver.py", line 503, in send_command
    self.socket.sendall(command.encode("utf-8"))
ConnectionResetError: [WinError 10054] 远程主机强迫关闭了一个现有的连接。

During handling of the above exception, another exception occurred:

Traceback (most recent call last):
  File "D:\conda\lib\site-packages\py4j\clientserver.py", line 503, in send_command
    self.socket.sendall(command.encode("utf-8"))
ConnectionResetError: [WinError 10054] 远程主机强迫关闭了一个现有的连接。

During handling of the above exception, another exception occurred:

Traceback (most recent call last):
  File "D:\conda\lib\site-packages\py4j\clientserver.py", line 503, in send_command
    self.socket.sendall(command.encode("utf-8"))
ConnectionResetError: [WinError 10054] 远程主机强迫关闭了一个现有的连接。

During handling of the above exception, another exception occurred:

Traceback (most recent call last):
  File "D:\conda\lib\site-packages\py4j\clientserver.py", line 503, in send_command
    self.socket.sendall(command.encode("utf-8"))
ConnectionResetError: [WinError 10054] 远程主机强迫关闭了一个现有的连接。

During handling of the above exception, another exception occurred:

Traceback (most recent call last):
  File "D:\conda\lib\site-packages\py4j\clientserver.py", line 503, in send_command
    self.socket.sendall(command.encode("utf-8"))
ConnectionResetError: [WinError 10054] 远程主机强迫关闭了一个现有的连接。
2025-05-16 23:51:24,822 - INFO - Closing down clientserver connection
2025-05-16 23:51:26,867 - INFO - Closing down clientserver connection
2025-05-16 23:51:26,868 - INFO - Closing down clientserver connection
2025-05-16 23:51:24,822 - INFO - Exception while sending command.
Traceback (most recent call last):
  File "D:\conda\lib\site-packages\pyspark\errors\exceptions\captured.py", line 169, in deco
    return f(*a, **kw)
  File "D:\conda\lib\site-packages\py4j\protocol.py", line 326, in get_return_value
    raise Py4JJavaError(
py4j.protocol.Py4JJavaError: <exception str() failed>

During handling of the above exception, another exception occurred:

Traceback (most recent call last):
  File "D:\conda\lib\site-packages\py4j\clientserver.py", line 511, in send_command
    answer = smart_decode(self.stream.readline()[:-1])
  File "D:\conda\lib\socket.py", line 669, in readinto
    return self._sock.recv_into(b)
ConnectionResetError: [WinError 10054] 远程主机强迫关闭了一个现有的连接。

During handling of the above exception, another exception occurred:

Traceback (most recent call last):
  File "D:\conda\lib\site-packages\py4j\clientserver.py", line 503, in send_command
    self.socket.sendall(command.encode("utf-8"))
ConnectionResetError: [WinError 10054] 远程主机强迫关闭了一个现有的连接。

During handling of the above exception, another exception occurred:

Traceback (most recent call last):
  File "D:\conda\lib\site-packages\py4j\clientserver.py", line 503, in send_command
    self.socket.sendall(command.encode("utf-8"))
ConnectionResetError: [WinError 10054] 远程主机强迫关闭了一个现有的连接。

During handling of the above exception, another exception occurred:

Traceback (most recent call last):
  File "D:\conda\lib\site-packages\py4j\clientserver.py", line 503, in send_command
    self.socket.sendall(command.encode("utf-8"))
ConnectionResetError: [WinError 10054] 远程主机强迫关闭了一个现有的连接。

During handling of the above exception, another exception occurred:

Traceback (most recent call last):
  File "D:\conda\lib\site-packages\py4j\clientserver.py", line 503, in send_command
    self.socket.sendall(command.encode("utf-8"))
ConnectionResetError: [WinError 10054] 远程主机强迫关闭了一个现有的连接。

During handling of the above exception, another exception occurred:

Traceback (most recent call last):
  File "D:\conda\lib\site-packages\py4j\clientserver.py", line 503, in send_command
    self.socket.sendall(command.encode("utf-8"))
ConnectionResetError: [WinError 10054] 远程主机强迫关闭了一个现有的连接。

During handling of the above exception, another exception occurred:

Traceback (most recent call last):
  File "D:\conda\lib\site-packages\py4j\clientserver.py", line 503, in send_command
    self.socket.sendall(command.encode("utf-8"))
ConnectionResetError: [WinError 10054] 远程主机强迫关闭了一个现有的连接。

During handling of the above exception, another exception occurred:

Traceback (most recent call last):
  File "D:\conda\lib\site-packages\py4j\clientserver.py", line 503, in send_command
    self.socket.sendall(command.encode("utf-8"))
ConnectionResetError: [WinError 10054] 远程主机强迫关闭了一个现有的连接。

During handling of the above exception, another exception occurred:

Traceback (most recent call last):
  File "D:\conda\lib\site-packages\py4j\clientserver.py", line 503, in send_command
    self.socket.sendall(command.encode("utf-8"))
ConnectionResetError: [WinError 10054] 远程主机强迫关闭了一个现有的连接。

During handling of the above exception, another exception occurred:

Traceback (most recent call last):
  File "D:\conda\lib\site-packages\py4j\clientserver.py", line 503, in send_command
    self.socket.sendall(command.encode("utf-8"))
ConnectionResetError: [WinError 10054] 远程主机强迫关闭了一个现有的连接。

During handling of the above exception, another exception occurred:

Traceback (most recent call last):
  File "D:\conda\lib\site-packages\py4j\clientserver.py", line 503, in send_command
    self.socket.sendall(command.encode("utf-8"))
ConnectionResetError: [WinError 10054] 远程主机强迫关闭了一个现有的连接。

During handling of the above exception, another exception occurred:

Traceback (most recent call last):
  File "D:\conda\lib\site-packages\py4j\clientserver.py", line 503, in send_command
    self.socket.sendall(command.encode("utf-8"))
ConnectionResetError: [WinError 10054] 远程主机强迫关闭了一个现有的连接。

During handling of the above exception, another exception occurred:

Traceback (most recent call last):
  File "D:\conda\lib\site-packages\py4j\clientserver.py", line 503, in send_command
    self.socket.sendall(command.encode("utf-8"))
ConnectionResetError: [WinError 10054] 远程主机强迫关闭了一个现有的连接。

During handling of the above exception, another exception occurred:

Traceback (most recent call last):
  File "D:\conda\lib\site-packages\py4j\clientserver.py", line 503, in send_command
    self.socket.sendall(command.encode("utf-8"))
ConnectionResetError: [WinError 10054] 远程主机强迫关闭了一个现有的连接。

During handling of the above exception, another exception occurred:

Traceback (most recent call last):
  File "D:\conda\lib\site-packages\py4j\clientserver.py", line 503, in send_command
    self.socket.sendall(command.encode("utf-8"))
ConnectionResetError: [WinError 10054] 远程主机强迫关闭了一个现有的连接。

During handling of the above exception, another exception occurred:

Traceback (most recent call last):
  File "D:\conda\lib\site-packages\py4j\clientserver.py", line 503, in send_command
    self.socket.sendall(command.encode("utf-8"))
ConnectionResetError: [WinError 10054] 远程主机强迫关闭了一个现有的连接。

During handling of the above exception, another exception occurred:

Traceback (most recent call last):
  File "D:\conda\lib\site-packages\py4j\clientserver.py", line 503, in send_command
    self.socket.sendall(command.encode("utf-8"))
ConnectionResetError: [WinError 10054] 远程主机强迫关闭了一个现有的连接。

During handling of the above exception, another exception occurred:

Traceback (most recent call last):
  File "D:\conda\lib\site-packages\py4j\clientserver.py", line 503, in send_command
    self.socket.sendall(command.encode("utf-8"))
ConnectionResetError: [WinError 10054] 远程主机强迫关闭了一个现有的连接。

During handling of the above exception, another exception occurred:

Traceback (most recent call last):
  File "D:\conda\lib\site-packages\py4j\clientserver.py", line 503, in send_command
    self.socket.sendall(command.encode("utf-8"))
ConnectionResetError: [WinError 10054] 远程主机强迫关闭了一个现有的连接。

During handling of the above exception, another exception occurred:

Traceback (most recent call last):
  File "D:\conda\lib\site-packages\py4j\clientserver.py", line 503, in send_command
    self.socket.sendall(command.encode("utf-8"))
ConnectionResetError: [WinError 10054] 远程主机强迫关闭了一个现有的连接。

During handling of the above exception, another exception occurred:

Traceback (most recent call last):
  File "D:\conda\lib\site-packages\py4j\clientserver.py", line 503, in send_command
    self.socket.sendall(command.encode("utf-8"))
ConnectionResetError: [WinError 10054] 远程主机强迫关闭了一个现有的连接。

During handling of the above exception, another exception occurred:

Traceback (most recent call last):
  File "D:\conda\lib\site-packages\py4j\clientserver.py", line 503, in send_command
    self.socket.sendall(command.encode("utf-8"))
ConnectionResetError: [WinError 10054] 远程主机强迫关闭了一个现有的连接。

During handling of the above exception, another exception occurred:

Traceback (most recent call last):
  File "D:\conda\lib\site-packages\py4j\clientserver.py", line 503, in send_command
    self.socket.sendall(command.encode("utf-8"))
ConnectionResetError: [WinError 10054] 远程主机强迫关闭了一个现有的连接。

During handling of the above exception, another exception occurred:

Traceback (most recent call last):
  File "D:\conda\lib\site-packages\py4j\clientserver.py", line 503, in send_command
    self.socket.sendall(command.encode("utf-8"))
ConnectionResetError: [WinError 10054] 远程主机强迫关闭了一个现有的连接。

During handling of the above exception, another exception occurred:

Traceback (most recent call last):
  File "D:\conda\lib\site-packages\py4j\clientserver.py", line 503, in send_command
    self.socket.sendall(command.encode("utf-8"))
ConnectionResetError: [WinError 10054] 远程主机强迫关闭了一个现有的连接。

During handling of the above exception, another exception occurred:

Traceback (most recent call last):
  File "D:\conda\lib\site-packages\py4j\clientserver.py", line 503, in send_command
    self.socket.sendall(command.encode("utf-8"))
ConnectionResetError: [WinError 10054] 远程主机强迫关闭了一个现有的连接。

During handling of the above exception, another exception occurred:

Traceback (most recent call last):
  File "D:\conda\lib\site-packages\py4j\clientserver.py", line 503, in send_command
    self.socket.sendall(command.encode("utf-8"))
ConnectionResetError: [WinError 10054] 远程主机强迫关闭了一个现有的连接。

During handling of the above exception, another exception occurred:

Traceback (most recent call last):
  File "D:\conda\lib\site-packages\py4j\clientserver.py", line 503, in send_command
    self.socket.sendall(command.encode("utf-8"))
ConnectionResetError: [WinError 10054] 远程主机强迫关闭了一个现有的连接。

During handling of the above exception, another exception occurred:

Traceback (most recent call last):
  File "D:\conda\lib\site-packages\py4j\clientserver.py", line 503, in send_command
    self.socket.sendall(command.encode("utf-8"))
ConnectionResetError: [WinError 10054] 远程主机强迫关闭了一个现有的连接。

During handling of the above exception, another exception occurred:

Traceback (most recent call last):
  File "D:\conda\lib\site-packages\py4j\clientserver.py", line 503, in send_command
    self.socket.sendall(command.encode("utf-8"))
ConnectionResetError: [WinError 10054] 远程主机强迫关闭了一个现有的连接。

During handling of the above exception, another exception occurred:

Traceback (most recent call last):
  File "D:\conda\lib\site-packages\py4j\clientserver.py", line 503, in send_command
    self.socket.sendall(command.encode("utf-8"))
ConnectionResetError: [WinError 10054] 远程主机强迫关闭了一个现有的连接。

During handling of the above exception, another exception occurred:

Traceback (most recent call last):
  File "D:\conda\lib\site-packages\py4j\clientserver.py", line 503, in send_command
    self.socket.sendall(command.encode("utf-8"))
ConnectionResetError: [WinError 10054] 远程主机强迫关闭了一个现有的连接。

During handling of the above exception, another exception occurred:

Traceback (most recent call last):
  File "D:\conda\lib\site-packages\py4j\clientserver.py", line 503, in send_command
    self.socket.sendall(command.encode("utf-8"))
ConnectionResetError: [WinError 10054] 远程主机强迫关闭了一个现有的连接。

During handling of the above exception, another exception occurred:

Traceback (most recent call last):
  File "D:\conda\lib\site-packages\py4j\clientserver.py", line 503, in send_command
    self.socket.sendall(command.encode("utf-8"))
ConnectionResetError: [WinError 10054] 远程主机强迫关闭了一个现有的连接。

During handling of the above exception, another exception occurred:

Traceback (most recent call last):
  File "D:\conda\lib\site-packages\py4j\clientserver.py", line 503, in send_command
    self.socket.sendall(command.encode("utf-8"))
ConnectionResetError: [WinError 10054] 远程主机强迫关闭了一个现有的连接。

During handling of the above exception, another exception occurred:

Traceback (most recent call last):
  File "D:\conda\lib\site-packages\py4j\clientserver.py", line 503, in send_command
    self.socket.sendall(command.encode("utf-8"))
ConnectionResetError: [WinError 10054] 远程主机强迫关闭了一个现有的连接。

During handling of the above exception, another exception occurred:

Traceback (most recent call last):
  File "D:\conda\lib\site-packages\py4j\clientserver.py", line 503, in send_command
    self.socket.sendall(command.encode("utf-8"))
ConnectionResetError: [WinError 10054] 远程主机强迫关闭了一个现有的连接。

During handling of the above exception, another exception occurred:

Traceback (most recent call last):
  File "D:\conda\lib\site-packages\py4j\clientserver.py", line 503, in send_command
    self.socket.sendall(command.encode("utf-8"))
ConnectionResetError: [WinError 10054] 远程主机强迫关闭了一个现有的连接。

During handling of the above exception, another exception occurred:

Traceback (most recent call last):
  File "D:\conda\lib\site-packages\py4j\clientserver.py", line 503, in send_command
    self.socket.sendall(command.encode("utf-8"))
ConnectionResetError: [WinError 10054] 远程主机强迫关闭了一个现有的连接。

During handling of the above exception, another exception occurred:

Traceback (most recent call last):
  File "D:\conda\lib\site-packages\py4j\clientserver.py", line 503, in send_command
    self.socket.sendall(command.encode("utf-8"))
ConnectionResetError: [WinError 10054] 远程主机强迫关闭了一个现有的连接。

During handling of the above exception, another exception occurred:

Traceback (most recent call last):
  File "D:\conda\lib\site-packages\py4j\clientserver.py", line 503, in send_command
    self.socket.sendall(command.encode("utf-8"))
ConnectionResetError: [WinError 10054] 远程主机强迫关闭了一个现有的连接。

During handling of the above exception, another exception occurred:

Traceback (most recent call last):
  File "D:\conda\lib\site-packages\py4j\clientserver.py", line 503, in send_command
    self.socket.sendall(command.encode("utf-8"))
ConnectionResetError: [WinError 10054] 远程主机强迫关闭了一个现有的连接。

During handling of the above exception, another exception occurred:

Traceback (most recent call last):
  File "D:\conda\lib\site-packages\py4j\clientserver.py", line 503, in send_command
    self.socket.sendall(command.encode("utf-8"))
ConnectionResetError: [WinError 10054] 远程主机强迫关闭了一个现有的连接。

During handling of the above exception, another exception occurred:

Traceback (most recent call last):
  File "D:\conda\lib\site-packages\py4j\java_gateway.py", line 1038, in send_command
    response = connection.send_command(command)
  File "D:\conda\lib\site-packages\py4j\clientserver.py", line 506, in send_command
    raise Py4JNetworkError(
py4j.protocol.Py4JNetworkError: Error while sending
2025-05-16 23:51:28,901 - INFO - Closing down clientserver connection
2025-05-16 23:51:28,902 - INFO - Closing down clientserver connection
2025-05-16 23:51:12,500 - INFO - Error while sending or receiving.
Traceback (most recent call last):
  File "D:\conda\lib\site-packages\pyspark\errors\exceptions\captured.py", line 169, in deco
    return f(*a, **kw)
  File "D:\conda\lib\site-packages\py4j\protocol.py", line 326, in get_return_value
    raise Py4JJavaError(
py4j.protocol.Py4JJavaError: <exception str() failed>

During handling of the above exception, another exception occurred:

Traceback (most recent call last):
  File "D:\conda\lib\site-packages\py4j\clientserver.py", line 511, in send_command
    answer = smart_decode(self.stream.readline()[:-1])
  File "D:\conda\lib\socket.py", line 669, in readinto
    return self._sock.recv_into(b)
ConnectionResetError: [WinError 10054] 远程主机强迫关闭了一个现有的连接。

During handling of the above exception, another exception occurred:

Traceback (most recent call last):
  File "D:\conda\lib\site-packages\py4j\clientserver.py", line 503, in send_command
    self.socket.sendall(command.encode("utf-8"))
ConnectionResetError: [WinError 10054] 远程主机强迫关闭了一个现有的连接。

During handling of the above exception, another exception occurred:

Traceback (most recent call last):
  File "D:\conda\lib\site-packages\py4j\clientserver.py", line 503, in send_command
    self.socket.sendall(command.encode("utf-8"))
ConnectionResetError: [WinError 10054] 远程主机强迫关闭了一个现有的连接。

During handling of the above exception, another exception occurred:

Traceback (most recent call last):
  File "D:\conda\lib\site-packages\py4j\clientserver.py", line 503, in send_command
    self.socket.sendall(command.encode("utf-8"))
ConnectionResetError: [WinError 10054] 远程主机强迫关闭了一个现有的连接。

During handling of the above exception, another exception occurred:

Traceback (most recent call last):
  File "D:\conda\lib\site-packages\py4j\clientserver.py", line 503, in send_command
    self.socket.sendall(command.encode("utf-8"))
ConnectionResetError: [WinError 10054] 远程主机强迫关闭了一个现有的连接。

During handling of the above exception, another exception occurred:

Traceback (most recent call last):
  File "D:\conda\lib\site-packages\py4j\clientserver.py", line 503, in send_command
    self.socket.sendall(command.encode("utf-8"))
ConnectionResetError: [WinError 10054] 远程主机强迫关闭了一个现有的连接。

During handling of the above exception, another exception occurred:

Traceback (most recent call last):
  File "D:\conda\lib\site-packages\py4j\clientserver.py", line 503, in send_command
    self.socket.sendall(command.encode("utf-8"))
ConnectionResetError: [WinError 10054] 远程主机强迫关闭了一个现有的连接。

During handling of the above exception, another exception occurred:

Traceback (most recent call last):
  File "D:\conda\lib\site-packages\py4j\clientserver.py", line 503, in send_command
    self.socket.sendall(command.encode("utf-8"))
ConnectionResetError: [WinError 10054] 远程主机强迫关闭了一个现有的连接。

During handling of the above exception, another exception occurred:

Traceback (most recent call last):
  File "D:\conda\lib\site-packages\py4j\clientserver.py", line 503, in send_command
    self.socket.sendall(command.encode("utf-8"))
ConnectionResetError: [WinError 10054] 远程主机强迫关闭了一个现有的连接。

During handling of the above exception, another exception occurred:

Traceback (most recent call last):
  File "D:\conda\lib\site-packages\py4j\clientserver.py", line 503, in send_command
    self.socket.sendall(command.encode("utf-8"))
ConnectionResetError: [WinError 10054] 远程主机强迫关闭了一个现有的连接。

During handling of the above exception, another exception occurred:

Traceback (most recent call last):
  File "D:\conda\lib\site-packages\py4j\clientserver.py", line 503, in send_command
    self.socket.sendall(command.encode("utf-8"))
ConnectionResetError: [WinError 10054] 远程主机强迫关闭了一个现有的连接。

During handling of the above exception, another exception occurred:

Traceback (most recent call last):
  File "D:\conda\lib\site-packages\py4j\clientserver.py", line 503, in send_command
    self.socket.sendall(command.encode("utf-8"))
ConnectionResetError: [WinError 10054] 远程主机强迫关闭了一个现有的连接。

During handling of the above exception, another exception occurred:

Traceback (most recent call last):
  File "D:\conda\lib\site-packages\py4j\clientserver.py", line 503, in send_command
    self.socket.sendall(command.encode("utf-8"))
ConnectionResetError: [WinError 10054] 远程主机强迫关闭了一个现有的连接。

During handling of the above exception, another exception occurred:

Traceback (most recent call last):
  File "D:\conda\lib\site-packages\py4j\clientserver.py", line 503, in send_command
    self.socket.sendall(command.encode("utf-8"))
ConnectionResetError: [WinError 10054] 远程主机强迫关闭了一个现有的连接。

During handling of the above exception, another exception occurred:

Traceback (most recent call last):
  File "D:\conda\lib\site-packages\py4j\clientserver.py", line 503, in send_command
    self.socket.sendall(command.encode("utf-8"))
ConnectionResetError: [WinError 10054] 远程主机强迫关闭了一个现有的连接。

During handling of the above exception, another exception occurred:

Traceback (most recent call last):
  File "D:\conda\lib\site-packages\py4j\clientserver.py", line 503, in send_command
    self.socket.sendall(command.encode("utf-8"))
ConnectionResetError: [WinError 10054] 远程主机强迫关闭了一个现有的连接。

During handling of the above exception, another exception occurred:

Traceback (most recent call last):
  File "D:\conda\lib\site-packages\py4j\clientserver.py", line 503, in send_command
    self.socket.sendall(command.encode("utf-8"))
ConnectionResetError: [WinError 10054] 远程主机强迫关闭了一个现有的连接。

During handling of the above exception, another exception occurred:

Traceback (most recent call last):
  File "D:\conda\lib\site-packages\py4j\clientserver.py", line 503, in send_command
    self.socket.sendall(command.encode("utf-8"))
ConnectionResetError: [WinError 10054] 远程主机强迫关闭了一个现有的连接。

During handling of the above exception, another exception occurred:

Traceback (most recent call last):
  File "D:\conda\lib\site-packages\py4j\clientserver.py", line 503, in send_command
    self.socket.sendall(command.encode("utf-8"))
ConnectionResetError: [WinError 10054] 远程主机强迫关闭了一个现有的连接。

During handling of the above exception, another exception occurred:

Traceback (most recent call last):
  File "D:\conda\lib\site-packages\py4j\clientserver.py", line 503, in send_command
    self.socket.sendall(command.encode("utf-8"))
ConnectionResetError: [WinError 10054] 远程主机强迫关闭了一个现有的连接。

During handling of the above exception, another exception occurred:

Traceback (most recent call last):
  File "D:\conda\lib\site-packages\py4j\clientserver.py", line 503, in send_command
    self.socket.sendall(command.encode("utf-8"))
ConnectionResetError: [WinError 10054] 远程主机强迫关闭了一个现有的连接。

During handling of the above exception, another exception occurred:

Traceback (most recent call last):
  File "D:\conda\lib\site-packages\py4j\clientserver.py", line 503, in send_command
    self.socket.sendall(command.encode("utf-8"))
ConnectionResetError: [WinError 10054] 远程主机强迫关闭了一个现有的连接。

During handling of the above exception, another exception occurred:

Traceback (most recent call last):
  File "D:\conda\lib\site-packages\py4j\clientserver.py", line 503, in send_command
    self.socket.sendall(command.encode("utf-8"))
ConnectionResetError: [WinError 10054] 远程主机强迫关闭了一个现有的连接。

During handling of the above exception, another exception occurred:

Traceback (most recent call last):
  File "D:\conda\lib\site-packages\py4j\clientserver.py", line 503, in send_command
    self.socket.sendall(command.encode("utf-8"))
ConnectionResetError: [WinError 10054] 远程主机强迫关闭了一个现有的连接。

During handling of the above exception, another exception occurred:

Traceback (most recent call last):
  File "D:\conda\lib\site-packages\py4j\clientserver.py", line 503, in send_command
    self.socket.sendall(command.encode("utf-8"))
ConnectionResetError: [WinError 10054] 远程主机强迫关闭了一个现有的连接。

During handling of the above exception, another exception occurred:

Traceback (most recent call last):
  File "D:\conda\lib\site-packages\py4j\clientserver.py", line 503, in send_command
    self.socket.sendall(command.encode("utf-8"))
ConnectionResetError: [WinError 10054] 远程主机强迫关闭了一个现有的连接。

During handling of the above exception, another exception occurred:

Traceback (most recent call last):
  File "D:\conda\lib\site-packages\py4j\clientserver.py", line 503, in send_command
    self.socket.sendall(command.encode("utf-8"))
ConnectionResetError: [WinError 10054] 远程主机强迫关闭了一个现有的连接。

During handling of the above exception, another exception occurred:

Traceback (most recent call last):
  File "D:\conda\lib\site-packages\py4j\clientserver.py", line 503, in send_command
    self.socket.sendall(command.encode("utf-8"))
ConnectionResetError: [WinError 10054] 远程主机强迫关闭了一个现有的连接。

During handling of the above exception, another exception occurred:

Traceback (most recent call last):
  File "D:\conda\lib\site-packages\py4j\clientserver.py", line 503, in send_command
    self.socket.sendall(command.encode("utf-8"))
ConnectionResetError: [WinError 10054] 远程主机强迫关闭了一个现有的连接。

During handling of the above exception, another exception occurred:

Traceback (most recent call last):
  File "D:\conda\lib\site-packages\py4j\clientserver.py", line 503, in send_command
    self.socket.sendall(command.encode("utf-8"))
ConnectionResetError: [WinError 10054] 远程主机强迫关闭了一个现有的连接。

During handling of the above exception, another exception occurred:

Traceback (most recent call last):
  File "D:\conda\lib\site-packages\py4j\clientserver.py", line 503, in send_command
    self.socket.sendall(command.encode("utf-8"))
ConnectionResetError: [WinError 10054] 远程主机强迫关闭了一个现有的连接。

During handling of the above exception, another exception occurred:

Traceback (most recent call last):
  File "D:\conda\lib\site-packages\py4j\clientserver.py", line 503, in send_command
    self.socket.sendall(command.encode("utf-8"))
ConnectionResetError: [WinError 10054] 远程主机强迫关闭了一个现有的连接。

During handling of the above exception, another exception occurred:

Traceback (most recent call last):
  File "D:\conda\lib\site-packages\py4j\clientserver.py", line 503, in send_command
    self.socket.sendall(command.encode("utf-8"))
ConnectionResetError: [WinError 10054] 远程主机强迫关闭了一个现有的连接。

During handling of the above exception, another exception occurred:

Traceback (most recent call last):
  File "D:\conda\lib\site-packages\py4j\clientserver.py", line 503, in send_command
    self.socket.sendall(command.encode("utf-8"))
ConnectionResetError: [WinError 10054] 远程主机强迫关闭了一个现有的连接。

During handling of the above exception, another exception occurred:

Traceback (most recent call last):
  File "D:\conda\lib\site-packages\py4j\clientserver.py", line 503, in send_command
    self.socket.sendall(command.encode("utf-8"))
ConnectionResetError: [WinError 10054] 远程主机强迫关闭了一个现有的连接。

During handling of the above exception, another exception occurred:

Traceback (most recent call last):
  File "D:\conda\lib\site-packages\py4j\clientserver.py", line 503, in send_command
    self.socket.sendall(command.encode("utf-8"))
ConnectionResetError: [WinError 10054] 远程主机强迫关闭了一个现有的连接。

During handling of the above exception, another exception occurred:

Traceback (most recent call last):
  File "D:\conda\lib\site-packages\py4j\clientserver.py", line 503, in send_command
    self.socket.sendall(command.encode("utf-8"))
ConnectionResetError: [WinError 10054] 远程主机强迫关闭了一个现有的连接。

During handling of the above exception, another exception occurred:

Traceback (most recent call last):
  File "D:\conda\lib\site-packages\py4j\clientserver.py", line 503, in send_command
    self.socket.sendall(command.encode("utf-8"))
ConnectionResetError: [WinError 10054] 远程主机强迫关闭了一个现有的连接。

During handling of the above exception, another exception occurred:

Traceback (most recent call last):
  File "D:\conda\lib\site-packages\py4j\clientserver.py", line 503, in send_command
    self.socket.sendall(command.encode("utf-8"))
ConnectionResetError: [WinError 10054] 远程主机强迫关闭了一个现有的连接。

During handling of the above exception, another exception occurred:

Traceback (most recent call last):
  File "D:\conda\lib\site-packages\py4j\clientserver.py", line 503, in send_command
    self.socket.sendall(command.encode("utf-8"))
ConnectionResetError: [WinError 10054] 远程主机强迫关闭了一个现有的连接。

During handling of the above exception, another exception occurred:

Traceback (most recent call last):
  File "D:\conda\lib\site-packages\py4j\clientserver.py", line 503, in send_command
    self.socket.sendall(command.encode("utf-8"))
ConnectionResetError: [WinError 10054] 远程主机强迫关闭了一个现有的连接。

During handling of the above exception, another exception occurred:

Traceback (most recent call last):
  File "D:\conda\lib\site-packages\py4j\clientserver.py", line 503, in send_command
    self.socket.sendall(command.encode("utf-8"))
ConnectionResetError: [WinError 10054] 远程主机强迫关闭了一个现有的连接。
2025-05-16 23:51:28,909 - INFO - Closing down clientserver connection
2025-05-16 23:51:45,619 - INFO - SELECT DATABASE()
2025-05-16 23:51:45,620 - INFO - [raw sql] {}
2025-05-16 23:51:45,625 - INFO - SELECT @@sql_mode
2025-05-16 23:51:45,625 - INFO - [raw sql] {}
2025-05-16 23:51:45,627 - INFO - SELECT @@lower_case_table_names
2025-05-16 23:51:45,627 - INFO - [raw sql] {}
2025-05-16 23:51:45,628 - INFO - BEGIN (implicit)
2025-05-16 23:51:45,641 - INFO - SELECT users.phone, users.email, users.username, users.sex, users.description, users.photo, users.qrcode, users.password, users.id, users.created_at 
FROM users 
WHERE users.id = %(id_1)s
2025-05-16 23:51:45,642 - INFO - [generated in 0.00053s] {'id_1': 22}
2025-05-16 23:51:45,644 - INFO - SELECT users.phone, users.email, users.username, users.sex, users.description, users.photo, users.qrcode, users.password, users.id, users.created_at 
FROM users 
WHERE users.id = %(id_1)s
2025-05-16 23:51:45,645 - INFO - [cached since 0.003854s ago] {'id_1': 22}
2025-05-16 23:51:45,647 - INFO - SELECT users.phone, users.email, users.username, users.sex, users.description, users.photo, users.qrcode, users.password, users.id, users.created_at 
FROM users 
WHERE users.id = %(id_1)s
2025-05-16 23:51:45,647 - INFO - [cached since 0.006473s ago] {'id_1': 22}
2025-05-16 23:51:45,650 - INFO - SELECT users.phone, users.email, users.username, users.sex, users.description, users.photo, users.qrcode, users.password, users.id, users.created_at 
FROM users 
WHERE users.id = %(id_1)s
2025-05-16 23:51:45,650 - INFO - [cached since 0.009047s ago] {'id_1': 22}
2025-05-16 23:51:45,652 - INFO - SELECT users.phone, users.email, users.username, users.sex, users.description, users.photo, users.qrcode, users.password, users.id, users.created_at 
FROM users 
WHERE users.id = %(id_1)s
2025-05-16 23:51:45,652 - INFO - [cached since 0.01152s ago] {'id_1': 22}
2025-05-16 23:51:45,657 - INFO - ROLLBACK
2025-05-16 23:52:27,766 - INFO - Error while receiving.
Traceback (most recent call last):
  File "D:\conda\lib\site-packages\py4j\clientserver.py", line 511, in send_command
    answer = smart_decode(self.stream.readline()[:-1])
  File "D:\conda\lib\socket.py", line 669, in readinto
    return self._sock.recv_into(b)
ConnectionResetError: [WinError 10054] 远程主机强迫关闭了一个现有的连接。
2025-05-16 23:52:27,767 - INFO - Closing down clientserver connection
2025-05-16 23:52:27,768 - ERROR - Exception while sending command.
Traceback (most recent call last):
  File "D:\conda\lib\site-packages\py4j\clientserver.py", line 511, in send_command
    answer = smart_decode(self.stream.readline()[:-1])
  File "D:\conda\lib\socket.py", line 669, in readinto
    return self._sock.recv_into(b)
ConnectionResetError: [WinError 10054] 远程主机强迫关闭了一个现有的连接。

During handling of the above exception, another exception occurred:

Traceback (most recent call last):
  File "D:\conda\lib\site-packages\py4j\java_gateway.py", line 1038, in send_command
    response = connection.send_command(command)
  File "D:\conda\lib\site-packages\py4j\clientserver.py", line 539, in send_command
    raise Py4JNetworkError(
py4j.protocol.Py4JNetworkError: Error while sending or receiving
2025-05-16 23:52:27,769 - INFO - Closing down clientserver connection
2025-05-16 23:52:42,035 - INFO - SELECT DATABASE()
2025-05-16 23:52:42,035 - INFO - [raw sql] {}
2025-05-16 23:52:42,036 - INFO - SELECT @@sql_mode
2025-05-16 23:52:42,036 - INFO - [raw sql] {}
2025-05-16 23:52:42,037 - INFO - SELECT @@lower_case_table_names
2025-05-16 23:52:42,037 - INFO - [raw sql] {}
2025-05-16 23:52:42,038 - INFO - BEGIN (implicit)
2025-05-16 23:52:42,044 - INFO - SELECT users.phone, users.email, users.username, users.sex, users.description, users.photo, users.qrcode, users.password, users.id, users.created_at 
FROM users 
WHERE users.id = %(id_1)s
2025-05-16 23:52:42,044 - INFO - [generated in 0.00030s] {'id_1': 22}
2025-05-16 23:52:42,046 - INFO - SELECT users.phone, users.email, users.username, users.sex, users.description, users.photo, users.qrcode, users.password, users.id, users.created_at 
FROM users 
WHERE users.id = %(id_1)s
2025-05-16 23:52:42,046 - INFO - [cached since 0.002357s ago] {'id_1': 22}
2025-05-16 23:52:42,048 - INFO - SELECT users.phone, users.email, users.username, users.sex, users.description, users.photo, users.qrcode, users.password, users.id, users.created_at 
FROM users 
WHERE users.id = %(id_1)s
2025-05-16 23:52:42,048 - INFO - [cached since 0.004001s ago] {'id_1': 22}
2025-05-16 23:52:42,049 - INFO - SELECT users.phone, users.email, users.username, users.sex, users.description, users.photo, users.qrcode, users.password, users.id, users.created_at 
FROM users 
WHERE users.id = %(id_1)s
2025-05-16 23:52:42,049 - INFO - [cached since 0.005341s ago] {'id_1': 22}
2025-05-16 23:52:42,051 - INFO - SELECT users.phone, users.email, users.username, users.sex, users.description, users.photo, users.qrcode, users.password, users.id, users.created_at 
FROM users 
WHERE users.id = %(id_1)s
2025-05-16 23:52:42,051 - INFO - [cached since 0.006757s ago] {'id_1': 22}
2025-05-16 23:52:42,052 - INFO - ROLLBACK
2025-05-16 23:53:32,125 - INFO - Error while receiving.
Traceback (most recent call last):
  File "D:\conda\lib\site-packages\py4j\clientserver.py", line 511, in send_command
    answer = smart_decode(self.stream.readline()[:-1])
  File "D:\conda\lib\socket.py", line 669, in readinto
    return self._sock.recv_into(b)
ConnectionResetError: [WinError 10054] 远程主机强迫关闭了一个现有的连接。
2025-05-16 23:53:32,126 - INFO - Closing down clientserver connection
2025-05-16 23:53:32,128 - ERROR - Exception while sending command.
Traceback (most recent call last):
  File "D:\conda\lib\site-packages\py4j\clientserver.py", line 511, in send_command
    answer = smart_decode(self.stream.readline()[:-1])
  File "D:\conda\lib\socket.py", line 669, in readinto
    return self._sock.recv_into(b)
ConnectionResetError: [WinError 10054] 远程主机强迫关闭了一个现有的连接。

During handling of the above exception, another exception occurred:

Traceback (most recent call last):
  File "D:\conda\lib\site-packages\py4j\java_gateway.py", line 1038, in send_command
    response = connection.send_command(command)
  File "D:\conda\lib\site-packages\py4j\clientserver.py", line 539, in send_command
    raise Py4JNetworkError(
py4j.protocol.Py4JNetworkError: Error while sending or receiving
2025-05-16 23:53:32,129 - INFO - Closing down clientserver connection
2025-05-16 23:55:24,337 - INFO - Error while receiving.
Traceback (most recent call last):
  File "D:\conda\lib\site-packages\py4j\clientserver.py", line 511, in send_command
    answer = smart_decode(self.stream.readline()[:-1])
  File "D:\conda\lib\socket.py", line 669, in readinto
    return self._sock.recv_into(b)
ConnectionResetError: [WinError 10054] 远程主机强迫关闭了一个现有的连接。
2025-05-16 23:55:24,338 - INFO - Closing down clientserver connection
2025-05-16 23:55:24,338 - ERROR - Exception while sending command.
Traceback (most recent call last):
  File "D:\conda\lib\site-packages\py4j\clientserver.py", line 511, in send_command
    answer = smart_decode(self.stream.readline()[:-1])
  File "D:\conda\lib\socket.py", line 669, in readinto
    return self._sock.recv_into(b)
ConnectionResetError: [WinError 10054] 远程主机强迫关闭了一个现有的连接。

During handling of the above exception, another exception occurred:

Traceback (most recent call last):
  File "D:\conda\lib\site-packages\py4j\java_gateway.py", line 1038, in send_command
    response = connection.send_command(command)
  File "D:\conda\lib\site-packages\py4j\clientserver.py", line 539, in send_command
    raise Py4JNetworkError(
py4j.protocol.Py4JNetworkError: Error while sending or receiving
2025-05-16 23:55:24,340 - INFO - Closing down clientserver connection
2025-05-16 23:55:42,763 - INFO - SELECT DATABASE()
2025-05-16 23:55:42,763 - INFO - [raw sql] {}
2025-05-16 23:55:42,764 - INFO - SELECT @@sql_mode
2025-05-16 23:55:42,764 - INFO - [raw sql] {}
2025-05-16 23:55:42,765 - INFO - SELECT @@lower_case_table_names
2025-05-16 23:55:42,765 - INFO - [raw sql] {}
2025-05-16 23:55:42,766 - INFO - BEGIN (implicit)
2025-05-16 23:55:42,771 - INFO - SELECT users.phone, users.email, users.username, users.sex, users.description, users.photo, users.qrcode, users.password, users.id, users.created_at 
FROM users 
WHERE users.id = %(id_1)s
2025-05-16 23:55:42,771 - INFO - [generated in 0.00067s] {'id_1': 22}
2025-05-16 23:55:42,775 - INFO - SELECT users.phone, users.email, users.username, users.sex, users.description, users.photo, users.qrcode, users.password, users.id, users.created_at 
FROM users 
WHERE users.id = %(id_1)s
2025-05-16 23:55:42,775 - INFO - [cached since 0.00415s ago] {'id_1': 22}
2025-05-16 23:55:42,776 - INFO - SELECT users.phone, users.email, users.username, users.sex, users.description, users.photo, users.qrcode, users.password, users.id, users.created_at 
FROM users 
WHERE users.id = %(id_1)s
2025-05-16 23:55:42,777 - INFO - [cached since 0.005968s ago] {'id_1': 22}
2025-05-16 23:55:42,778 - INFO - SELECT users.phone, users.email, users.username, users.sex, users.description, users.photo, users.qrcode, users.password, users.id, users.created_at 
FROM users 
WHERE users.id = %(id_1)s
2025-05-16 23:55:42,778 - INFO - [cached since 0.007592s ago] {'id_1': 22}
2025-05-16 23:55:42,780 - INFO - SELECT users.phone, users.email, users.username, users.sex, users.description, users.photo, users.qrcode, users.password, users.id, users.created_at 
FROM users 
WHERE users.id = %(id_1)s
2025-05-16 23:55:42,780 - INFO - [cached since 0.009064s ago] {'id_1': 22}
2025-05-16 23:55:42,781 - INFO - ROLLBACK
2025-05-16 23:56:08,492 - INFO - Error while receiving.
Traceback (most recent call last):
  File "D:\conda\lib\site-packages\py4j\clientserver.py", line 511, in send_command
    answer = smart_decode(self.stream.readline()[:-1])
  File "D:\conda\lib\socket.py", line 669, in readinto
    return self._sock.recv_into(b)
ConnectionResetError: [WinError 10054] 远程主机强迫关闭了一个现有的连接。
2025-05-16 23:56:08,493 - INFO - Closing down clientserver connection
2025-05-16 23:56:08,493 - ERROR - Exception while sending command.
Traceback (most recent call last):
  File "D:\conda\lib\site-packages\py4j\clientserver.py", line 511, in send_command
    answer = smart_decode(self.stream.readline()[:-1])
  File "D:\conda\lib\socket.py", line 669, in readinto
    return self._sock.recv_into(b)
ConnectionResetError: [WinError 10054] 远程主机强迫关闭了一个现有的连接。

During handling of the above exception, another exception occurred:

Traceback (most recent call last):
  File "D:\conda\lib\site-packages\py4j\java_gateway.py", line 1038, in send_command
    response = connection.send_command(command)
  File "D:\conda\lib\site-packages\py4j\clientserver.py", line 539, in send_command
    raise Py4JNetworkError(
py4j.protocol.Py4JNetworkError: Error while sending or receiving
2025-05-16 23:56:08,494 - INFO - Closing down clientserver connection
2025-05-16 23:57:15,504 - INFO - Error while receiving.
Traceback (most recent call last):
  File "D:\conda\lib\site-packages\py4j\clientserver.py", line 511, in send_command
    answer = smart_decode(self.stream.readline()[:-1])
  File "D:\conda\lib\socket.py", line 669, in readinto
    return self._sock.recv_into(b)
ConnectionResetError: [WinError 10054] 远程主机强迫关闭了一个现有的连接。
2025-05-16 23:57:15,508 - INFO - Closing down clientserver connection
2025-05-16 23:57:15,508 - ERROR - Exception while sending command.
Traceback (most recent call last):
  File "D:\conda\lib\site-packages\py4j\clientserver.py", line 511, in send_command
    answer = smart_decode(self.stream.readline()[:-1])
  File "D:\conda\lib\socket.py", line 669, in readinto
    return self._sock.recv_into(b)
ConnectionResetError: [WinError 10054] 远程主机强迫关闭了一个现有的连接。

During handling of the above exception, another exception occurred:

Traceback (most recent call last):
  File "D:\conda\lib\site-packages\py4j\java_gateway.py", line 1038, in send_command
    response = connection.send_command(command)
  File "D:\conda\lib\site-packages\py4j\clientserver.py", line 539, in send_command
    raise Py4JNetworkError(
py4j.protocol.Py4JNetworkError: Error while sending or receiving
2025-05-16 23:57:15,508 - INFO - Closing down clientserver connection
2025-05-16 23:57:57,214 - INFO - Error while receiving.
Traceback (most recent call last):
  File "D:\conda\lib\site-packages\py4j\clientserver.py", line 511, in send_command
    answer = smart_decode(self.stream.readline()[:-1])
  File "D:\conda\lib\socket.py", line 669, in readinto
    return self._sock.recv_into(b)
ConnectionResetError: [WinError 10054] 远程主机强迫关闭了一个现有的连接。
2025-05-16 23:57:57,216 - INFO - Closing down clientserver connection
2025-05-16 23:57:57,216 - ERROR - Exception while sending command.
Traceback (most recent call last):
  File "D:\conda\lib\site-packages\py4j\clientserver.py", line 511, in send_command
    answer = smart_decode(self.stream.readline()[:-1])
  File "D:\conda\lib\socket.py", line 669, in readinto
    return self._sock.recv_into(b)
ConnectionResetError: [WinError 10054] 远程主机强迫关闭了一个现有的连接。

During handling of the above exception, another exception occurred:

Traceback (most recent call last):
  File "D:\conda\lib\site-packages\py4j\java_gateway.py", line 1038, in send_command
    response = connection.send_command(command)
  File "D:\conda\lib\site-packages\py4j\clientserver.py", line 539, in send_command
    raise Py4JNetworkError(
py4j.protocol.Py4JNetworkError: Error while sending or receiving
2025-05-16 23:57:57,217 - INFO - Closing down clientserver connection
2025-05-16 23:58:13,760 - INFO - SELECT DATABASE()
2025-05-16 23:58:13,760 - INFO - [raw sql] {}
2025-05-16 23:58:13,763 - INFO - SELECT @@sql_mode
2025-05-16 23:58:13,763 - INFO - [raw sql] {}
2025-05-16 23:58:13,764 - INFO - SELECT @@lower_case_table_names
2025-05-16 23:58:13,764 - INFO - [raw sql] {}
2025-05-16 23:58:13,765 - INFO - BEGIN (implicit)
2025-05-16 23:58:13,769 - INFO - SELECT users.phone, users.email, users.username, users.sex, users.description, users.photo, users.qrcode, users.password, users.id, users.created_at 
FROM users 
WHERE users.id = %(id_1)s
2025-05-16 23:58:13,770 - INFO - [generated in 0.00029s] {'id_1': 22}
2025-05-16 23:58:13,773 - INFO - SELECT users.phone, users.email, users.username, users.sex, users.description, users.photo, users.qrcode, users.password, users.id, users.created_at 
FROM users 
WHERE users.id = %(id_1)s
2025-05-16 23:58:13,773 - INFO - [cached since 0.003555s ago] {'id_1': 22}
2025-05-16 23:58:13,774 - INFO - SELECT users.phone, users.email, users.username, users.sex, users.description, users.photo, users.qrcode, users.password, users.id, users.created_at 
FROM users 
WHERE users.id = %(id_1)s
2025-05-16 23:58:13,775 - INFO - [cached since 0.005208s ago] {'id_1': 22}
2025-05-16 23:58:13,776 - INFO - SELECT users.phone, users.email, users.username, users.sex, users.description, users.photo, users.qrcode, users.password, users.id, users.created_at 
FROM users 
WHERE users.id = %(id_1)s
2025-05-16 23:58:13,776 - INFO - [cached since 0.006625s ago] {'id_1': 22}
2025-05-16 23:58:13,777 - INFO - SELECT users.phone, users.email, users.username, users.sex, users.description, users.photo, users.qrcode, users.password, users.id, users.created_at 
FROM users 
WHERE users.id = %(id_1)s
2025-05-16 23:58:13,777 - INFO - [cached since 0.007981s ago] {'id_1': 22}
2025-05-16 23:58:13,779 - INFO - ROLLBACK
2025-05-17 00:00:16,333 - INFO - BEGIN (implicit)
2025-05-17 00:00:16,334 - INFO - SELECT users.phone, users.email, users.username, users.sex, users.description, users.photo, users.qrcode, users.password, users.id, users.created_at 
FROM users 
WHERE users.id = %(id_1)s
2025-05-17 00:00:16,334 - INFO - [cached since 122.6s ago] {'id_1': 22}
2025-05-17 00:00:16,335 - INFO - SELECT users.phone, users.email, users.username, users.sex, users.description, users.photo, users.qrcode, users.password, users.id, users.created_at 
FROM users 
WHERE users.id = %(id_1)s
2025-05-17 00:00:16,335 - INFO - [cached since 122.6s ago] {'id_1': 22}
2025-05-17 00:00:16,337 - INFO - SELECT users.phone, users.email, users.username, users.sex, users.description, users.photo, users.qrcode, users.password, users.id, users.created_at 
FROM users 
WHERE users.id = %(id_1)s
2025-05-17 00:00:16,337 - INFO - [cached since 122.6s ago] {'id_1': 22}
2025-05-17 00:00:16,340 - INFO - SELECT users.phone, users.email, users.username, users.sex, users.description, users.photo, users.qrcode, users.password, users.id, users.created_at 
FROM users 
WHERE users.id = %(id_1)s
2025-05-17 00:00:16,340 - INFO - [cached since 122.6s ago] {'id_1': 22}
2025-05-17 00:00:16,342 - INFO - SELECT users.phone, users.email, users.username, users.sex, users.description, users.photo, users.qrcode, users.password, users.id, users.created_at 
FROM users 
WHERE users.id = %(id_1)s
2025-05-17 00:00:16,342 - INFO - [cached since 122.6s ago] {'id_1': 22}
2025-05-17 00:00:16,344 - INFO - ROLLBACK
2025-05-17 00:00:27,668 - INFO - BEGIN (implicit)
2025-05-17 00:00:27,669 - INFO - SELECT users.phone, users.email, users.username, users.sex, users.description, users.photo, users.qrcode, users.password, users.id, users.created_at 
FROM users 
WHERE users.id = %(id_1)s
2025-05-17 00:00:27,669 - INFO - [cached since 133.9s ago] {'id_1': 22}
2025-05-17 00:00:27,672 - INFO - SELECT users.phone, users.email, users.username, users.sex, users.description, users.photo, users.qrcode, users.password, users.id, users.created_at 
FROM users 
WHERE users.id = %(id_1)s
2025-05-17 00:00:27,672 - INFO - [cached since 133.9s ago] {'id_1': 22}
2025-05-17 00:00:27,674 - INFO - SELECT users.phone, users.email, users.username, users.sex, users.description, users.photo, users.qrcode, users.password, users.id, users.created_at 
FROM users 
WHERE users.id = %(id_1)s
2025-05-17 00:00:27,675 - INFO - [cached since 133.9s ago] {'id_1': 22}
2025-05-17 00:00:27,676 - INFO - SELECT users.phone, users.email, users.username, users.sex, users.description, users.photo, users.qrcode, users.password, users.id, users.created_at 
FROM users 
WHERE users.id = %(id_1)s
2025-05-17 00:00:27,677 - INFO - [cached since 133.9s ago] {'id_1': 22}
2025-05-17 00:00:27,678 - INFO - SELECT users.phone, users.email, users.username, users.sex, users.description, users.photo, users.qrcode, users.password, users.id, users.created_at 
FROM users 
WHERE users.id = %(id_1)s
2025-05-17 00:00:27,678 - INFO - [cached since 133.9s ago] {'id_1': 22}
2025-05-17 00:00:27,682 - INFO - ROLLBACK
2025-05-17 00:00:29,533 - INFO - BEGIN (implicit)
2025-05-17 00:00:29,533 - INFO - SELECT users.phone, users.email, users.username, users.sex, users.description, users.photo, users.qrcode, users.password, users.id, users.created_at 
FROM users 
WHERE users.id = %(id_1)s
2025-05-17 00:00:29,534 - INFO - [cached since 135.8s ago] {'id_1': 22}
2025-05-17 00:00:29,536 - INFO - SELECT users.phone, users.email, users.username, users.sex, users.description, users.photo, users.qrcode, users.password, users.id, users.created_at 
FROM users 
WHERE users.id = %(id_1)s
2025-05-17 00:00:29,536 - INFO - [cached since 135.8s ago] {'id_1': 22}
2025-05-17 00:00:29,538 - INFO - SELECT users.phone, users.email, users.username, users.sex, users.description, users.photo, users.qrcode, users.password, users.id, users.created_at 
FROM users 
WHERE users.id = %(id_1)s
2025-05-17 00:00:29,538 - INFO - [cached since 135.8s ago] {'id_1': 22}
2025-05-17 00:00:29,541 - INFO - SELECT users.phone, users.email, users.username, users.sex, users.description, users.photo, users.qrcode, users.password, users.id, users.created_at 
FROM users 
WHERE users.id = %(id_1)s
2025-05-17 00:00:29,541 - INFO - [cached since 135.8s ago] {'id_1': 22}
2025-05-17 00:00:29,543 - INFO - SELECT users.phone, users.email, users.username, users.sex, users.description, users.photo, users.qrcode, users.password, users.id, users.created_at 
FROM users 
WHERE users.id = %(id_1)s
2025-05-17 00:00:29,544 - INFO - [cached since 135.8s ago] {'id_1': 22}
2025-05-17 00:00:29,546 - INFO - SELECT users.phone, users.email, users.username, users.sex, users.description, users.photo, users.qrcode, users.password, users.id, users.created_at 
FROM users 
WHERE users.id = %(id_1)s
2025-05-17 00:00:29,547 - INFO - [cached since 135.8s ago] {'id_1': 22}
2025-05-17 00:00:29,548 - INFO - SELECT users.phone, users.email, users.username, users.sex, users.description, users.photo, users.qrcode, users.password, users.id, users.created_at 
FROM users 
WHERE users.id = %(id_1)s
2025-05-17 00:00:29,548 - INFO - [cached since 135.8s ago] {'id_1': 22}
2025-05-17 00:00:29,549 - INFO - SELECT users.phone, users.email, users.username, users.sex, users.description, users.photo, users.qrcode, users.password, users.id, users.created_at 
FROM users 
WHERE users.id = %(id_1)s
2025-05-17 00:00:29,550 - INFO - [cached since 135.8s ago] {'id_1': 22}
2025-05-17 00:00:29,551 - INFO - SELECT users.phone, users.email, users.username, users.sex, users.description, users.photo, users.qrcode, users.password, users.id, users.created_at 
FROM users 
WHERE users.id = %(id_1)s
2025-05-17 00:00:29,551 - INFO - [cached since 135.8s ago] {'id_1': 22}
2025-05-17 00:00:29,552 - INFO - SELECT users.phone, users.email, users.username, users.sex, users.description, users.photo, users.qrcode, users.password, users.id, users.created_at 
FROM users 
WHERE users.id = %(id_1)s
2025-05-17 00:00:29,553 - INFO - [cached since 135.8s ago] {'id_1': 22}
2025-05-17 00:00:29,556 - INFO - ROLLBACK
2025-05-17 00:00:31,042 - INFO - BEGIN (implicit)
2025-05-17 00:00:31,042 - INFO - SELECT users.phone, users.email, users.username, users.sex, users.description, users.photo, users.qrcode, users.password, users.id, users.created_at 
FROM users 
WHERE users.id = %(id_1)s
2025-05-17 00:00:31,043 - INFO - [cached since 137.3s ago] {'id_1': 22}
2025-05-17 00:00:31,046 - INFO - SELECT users.phone, users.email, users.username, users.sex, users.description, users.photo, users.qrcode, users.password, users.id, users.created_at 
FROM users 
WHERE users.id = %(id_1)s
2025-05-17 00:00:31,046 - INFO - [cached since 137.3s ago] {'id_1': 22}
2025-05-17 00:00:31,048 - INFO - SELECT users.phone, users.email, users.username, users.sex, users.description, users.photo, users.qrcode, users.password, users.id, users.created_at 
FROM users 
WHERE users.id = %(id_1)s
2025-05-17 00:00:31,049 - INFO - [cached since 137.3s ago] {'id_1': 22}
2025-05-17 00:00:31,051 - INFO - SELECT users.phone, users.email, users.username, users.sex, users.description, users.photo, users.qrcode, users.password, users.id, users.created_at 
FROM users 
WHERE users.id = %(id_1)s
2025-05-17 00:00:31,051 - INFO - [cached since 137.3s ago] {'id_1': 22}
2025-05-17 00:00:31,053 - INFO - SELECT users.phone, users.email, users.username, users.sex, users.description, users.photo, users.qrcode, users.password, users.id, users.created_at 
FROM users 
WHERE users.id = %(id_1)s
2025-05-17 00:00:31,054 - INFO - [cached since 137.3s ago] {'id_1': 22}
2025-05-17 00:00:31,057 - INFO - SELECT users.phone, users.email, users.username, users.sex, users.description, users.photo, users.qrcode, users.password, users.id, users.created_at 
FROM users 
WHERE users.id = %(id_1)s
2025-05-17 00:00:31,057 - INFO - [cached since 137.3s ago] {'id_1': 22}
2025-05-17 00:00:31,059 - INFO - SELECT users.phone, users.email, users.username, users.sex, users.description, users.photo, users.qrcode, users.password, users.id, users.created_at 
FROM users 
WHERE users.id = %(id_1)s
2025-05-17 00:00:31,060 - INFO - [cached since 137.3s ago] {'id_1': 22}
2025-05-17 00:00:31,062 - INFO - SELECT users.phone, users.email, users.username, users.sex, users.description, users.photo, users.qrcode, users.password, users.id, users.created_at 
FROM users 
WHERE users.id = %(id_1)s
2025-05-17 00:00:31,062 - INFO - [cached since 137.3s ago] {'id_1': 22}
2025-05-17 00:00:31,065 - INFO - SELECT users.phone, users.email, users.username, users.sex, users.description, users.photo, users.qrcode, users.password, users.id, users.created_at 
FROM users 
WHERE users.id = %(id_1)s
2025-05-17 00:00:31,066 - INFO - [cached since 137.3s ago] {'id_1': 22}
2025-05-17 00:00:31,069 - INFO - SELECT users.phone, users.email, users.username, users.sex, users.description, users.photo, users.qrcode, users.password, users.id, users.created_at 
FROM users 
WHERE users.id = %(id_1)s
2025-05-17 00:00:31,069 - INFO - [cached since 137.3s ago] {'id_1': 22}
2025-05-17 00:00:31,073 - INFO - ROLLBACK
2025-05-17 00:01:32,429 - INFO - Error while receiving.
Traceback (most recent call last):
  File "D:\conda\lib\site-packages\py4j\clientserver.py", line 511, in send_command
    answer = smart_decode(self.stream.readline()[:-1])
  File "D:\conda\lib\socket.py", line 669, in readinto
    return self._sock.recv_into(b)
ConnectionResetError: [WinError 10054] 远程主机强迫关闭了一个现有的连接。
2025-05-17 00:01:32,430 - INFO - Closing down clientserver connection
2025-05-17 00:01:32,430 - ERROR - Exception while sending command.
Traceback (most recent call last):
  File "D:\conda\lib\site-packages\py4j\clientserver.py", line 511, in send_command
    answer = smart_decode(self.stream.readline()[:-1])
  File "D:\conda\lib\socket.py", line 669, in readinto
    return self._sock.recv_into(b)
ConnectionResetError: [WinError 10054] 远程主机强迫关闭了一个现有的连接。

During handling of the above exception, another exception occurred:

Traceback (most recent call last):
  File "D:\conda\lib\site-packages\py4j\java_gateway.py", line 1038, in send_command
    response = connection.send_command(command)
  File "D:\conda\lib\site-packages\py4j\clientserver.py", line 539, in send_command
    raise Py4JNetworkError(
py4j.protocol.Py4JNetworkError: Error while sending or receiving
2025-05-17 00:01:32,432 - INFO - Closing down clientserver connection
